Workbook

Sheet semana 1
B2: SEMANA | E2: CONSUMO DE PRODUTOS QUÍMICOS SAFRA 2026/2027
B3: 1 | C3: SEMANA 12/04/2026 A 19/04/2026
B4: Destilaria | C4: b | D4: Consumo | F4: Custos( R$ ) | I4: Gr / m³ | M4: Descrição | N4: Semana | O4: Safra 2026 | P4: Safra 2025
D5: SEMANAL | E5: SAFRA | F5: VALOR | G5: SEMANA | H5: SAFRA | I5: SEMANA | J5: SAFRA | K5: META | M5: AÇÚCAR VHP (scs.) | N5: 46469 | O5: =N5 -> 46469 | P5: 6640
B6: ÁC.SULFURICO | C6: kg | D6: 5981.82 | E6: =D6 -> 5981.82 | F6: 2.54 | G6: =E6*F6 -> 15193.823 | H6: =E6*F6 -> 15193.823 | I6: =IF($N$9=0,0,D6/$N$9*1000) -> 5.4840443 | J6: =IF($O$9=0,0,E6/$O$9*1000) -> 5.4840443 | K6: 9.8 | M6: AÇÚCAR CRISTAL (scs.) | O6: =N6 -> 0
B7: ANTIBIÓTICO | C7: kg | D7: 30 | E7: =D7 -> 30 | F7: 599 | G7: =E7*F7 -> 17970 | H7: =E7*F7 -> 17970 | I7: =IF($N$9=0,0,D7/$N$9*1000)*1000 -> 27.503557 | J7: =IF($O$9=0,0,E7/$O$9*1000)*1000 -> 27.503557 | K7: 6.8 | M7: ETANOL ANIDRO ( L ) | O7: =N7 -> 0
B8: ANTIESPUMANTE | C8: kg | D8: 1170 | E8: =D8 -> 1170 | F8: 12.81 | G8: =E8*F8 -> 14987.7 | H8: =E8*F8 -> 14987.7 | I8: =IF($N$9=0,0,D8/$N$9*1000)*1000 -> 1072.6387 | J8: =IF($O$9=0,0,E8/$O$9*1000)*1000 -> 1072.6387 | K8: 400 | M8: ETANOL HIDRATADO ( L ) | N8: 1090768 | O8: =N8 -> 1090768 | P8: 117223
B9: DISPERSANTE | C9: kg | D9: 122.21 | E9: =D9 -> 122.21 | F9: 25.15 | G9: =E9*F9 -> 3073.5815 | H9: =E9*F9 -> 3073.5815 | I9: =IF($N$9=0,0,D9/$N$9*1000)*1000 -> 112.04032 | J9: =IF($O$9=0,0,E9/$O$9*1000)*1000 -> 112.04032 | K9: 200 | M9: ETANOL TOTAL | N9: =SUM(N7:N8) -> 1090768 | O9: =SUM(O7:O8) -> 1090768
B10: NEUT.ALCOOL | C10: kg | E10: =D10 -> 0 | F10: 10.98 | G10: =E10*F10 -> 0 | H10: =E10*F10 -> 0 | I10: =IF($N$9=0,0,D10/$N$9*1000)*1000 -> 0 | J10: =IF($O$9=0,0,E10/$O$9*1000)*1000 -> 0 | K10: 10 | M10: AÇUCAR TOTAL | N10: =SUM(N5:N6) -> 46469 | O10: =SUM(O5:O6) -> 46469
B11: NUTRIENTES | C11: kg | D11: 2397.34 | E11: =D11 -> 2397.34 | F11: 4.13 | G11: =E11*F11 -> 9901.0142 | H11: =E11*F11 -> 9901.0142 | I11: =IF($N$9=0,0,D11/$N$9*1000)*1000 -> 2197.8459 | J11: =IF($O$9=0,0,E11/$O$9*1000)*1000 -> 2197.8459
B12: SODA CÁUSTICA | C12: kg | D12: 300 | E12: =D12 -> 300 | F12: 5.83 | G12: =E12*F12 -> 1749 | H12: =E12*F12 -> 1749 | I12: =IF($N$9=0,0,D12/$N$9*1000)*1000 -> 275.03557 | J12: =IF($O$9=0,0,E12/$O$9*1000)*1000 -> 275.03557 | K12: 400 | M12: MOAGEM ( Toneladas )
B13: FERMAPLUS | C13: kg | E13: =D13 -> 0 | F13: 6 | G13: =E13*F13 -> 0 | H13: =E13*F13 -> 0 | I13: =IF($N$9=0,0,D13/$N$9*1000)*1000 -> 0 | J13: =IF($O$9=0,0,E13/$O$9*1000)*1000 -> 0 | K13: 500 | M13: CANA MOÍDA | N13: SEMANA | O13: SAFRA 2026 | P13: SAFRA 2025
B14: MONENSINA | C14: Kg | E14: =D14 -> 0 | F14: 425 | G14: =E14*F14 -> 0 | H14: =E14*F14 -> 0 | I14: =IF($N$9=0,0,D14/$N$9*1000)*1000 -> 0 | J14: =IF($O$9=0,0,E14/$O$9*1000)*1000 -> 0 | K14: 3 | M14: PARA ETANOL | N14: 19348.047 | O14: =N14 -> 19348.047 | P14: 6738.662
M15: PARA AÇÚCAR | N15: 26096.293 | O15: =N15 -> 26096.293 | P15: 7356.378
B16: Fábrica | D16: Consumo | F16: Custos( R$ ) | I16: Gr / tc | M16: MOÍDA TOTAL | N16: =SUM(N14:N15) -> 45444.34 | O16: =SUM(O14:O15) -> 45444.34 | P16: 14095.04
D17: SEMANAL | E17: SAFRA | F17: VALOR | G17: SEMANA | H17: SAFRA | I17: SEMANA | J17: SAFRA | K17: META
B18: FLOCULANTE | C18: kg | D18: 375 | E18: =D18 -> 375 | F18: 21 | G18: =D18*F18 -> 7875 | H18: =E18*F18 -> 7875 | I18: =IF($N$10=0,0,D18/$N$16*1000) -> 8.2518527 | J18: =IF($O$10=0,0,E18/$O$16*1000) -> 8.2518527 | K18: 6.1 | M18: SETOR | N18: SEMANA | O18: SAFRA
B19: FLOCUL. FILTRO | C19: kg | D19: 325 | E19: =D19 -> 325 | F19: 15.63 | G19: =D19*F19 -> 5079.75 | H19: =E19*F19 -> 5079.75 | I19: =IF($N$10=0,0,D19/$N$16*1000) -> 7.1516057 | J19: =IF($O$10=0,0,E19/$O$16*1000) -> 7.1516057 | K19: 9 | M19: DESTILARIA | N19: =SUM(G6:G14) -> 62875.119 | O19: =SUM(H6:H14) -> 62875.119
B20: ENXOFRE | C20: kg | D20: 1000 | E20: =D20 -> 1000 | F20: 6.7 | G20: =D20*F20 -> 6700 | H20: =E20*F20 -> 6700 | I20: =IF($N$10=0,0,D20/$N$16*1000) -> 22.004941 | J20: =IF($O$10=0,0,E20/$O$16*1000) -> 22.004941 | K20: 51 | M20: FÁBRICA | N20: =SUM(G18:G26) -> 68559.75 | O20: =SUM(H18:H26) -> 68559.75
B21: AC.FOSFÓRICO | C21: kg | E21: =D21 -> 0 | F21: 5.85 | G21: =D21*F21 -> 0 | H21: =E21*F21 -> 0 | I21: =IF($N$10=0,0,D21/$N$16*1000) -> 0 | J21: =IF($O$10=0,0,E21/$O$16*1000) -> 0 | M21: MOENDA | N21: =SUM(G30:G36) -> 6374.3123 | O21: =SUM(H30:H36) -> 6374.3123
B22: CAL DOLOMÍTICA | C22: kg | D22: 34000 | E22: =D22 -> 34000 | F22: 1.03 | G22: =D22*F22 -> 35020 | H22: =E22*F22 -> 35020 | I22: =IF($N$10=0,0,D22/$N$16*1000) -> 748.16798 | J22: =IF($O$10=0,0,E22/$O$16*1000) -> 748.16798 | K22: 1000 | M22: ETA/CALD. | N22: =SUM(G40:G52) -> 21763.175 | O22: =SUM(H40:H52) -> 21763.175
B23: SODA CÁUSTICA | C23: kg | D23: 575 | E23: =D23 -> 575 | F23: 5.83 | G23: =D23*F23 -> 3352.25 | H23: =E23*F23 -> 3352.25 | I23: =IF($N$10=0,0,D23/$N$16*1000) -> 12.652841 | J23: =IF($O$10=0,0,E23/$O$16*1000) -> 12.652841 | K23: 13 | M23: CUSTO TOTAL (R$ ) | N23: =SUM(N19:N22) -> 159572.36 | O23: =SUM(O19:O22) -> 159572.36
B24: NEUT.VAPOR | C24: kg | D24: 427.05 | E24: =D24 -> 427.05 | F24: 8 | G24: =D24*F24 -> 3416.4 | H24: =E24*F24 -> 3416.4 | I24: =IF($N$10=0,0,D24/$N$16*1000) -> 9.3972099 | J24: =IF($O$10=0,0,E24/$O$16*1000) -> 9.3972099 | K24: 2.8
B25: ANTI-INCRUST. | C25: kg | D25: 1216.47 | E25: =D25 -> 1216.47 | F25: 5.85 | G25: =D25*F25 -> 7116.3495 | H25: =E25*F25 -> 7116.3495 | I25: =IF($N$10=0,0,D25/$N$16*1000) -> 26.76835 | J25: =IF($O$10=0,0,E25/$O$16*1000) -> 26.76835 | K25: 28 | M25: Setor | N25: Semana | P25: Safra
B26: CLARIFICANTE FL 40 | C26: Kg | E26: =D26 -> 0 | F26: 6.98 | G26: =D26*F26 -> 0 | H26: =E26*F26 -> 0 | I26: =IF($N$10=0,0,D26/$N$16*1000) -> 0 | J26: =IF($O$10=0,0,E26/$O$16*1000) -> 0 | K26: 21.3 | M26: DESTILARIA | N26: =IF($N$9=0,0,N19/$N$9*1000) -> 57.64298 | O26: R$/m³ | P26: =IF($O$9=0,0,O19/$O$9*1000) -> 57.64298 | Q26: R$/m³
M27: FÁBRICA | N27: =IF($N$10=0,0,N20/$N$16) -> 1.5086532 | O27: R$/tc | P27: =IF($O$10=0,0,O20/$O$16) -> 1.5086532 | Q27: R$/scs
B28: Moenda | D28: Consumo | F28: Custos( R$ ) | I28: Gr / tc | M28: MOENDA | N28: =IF($N$16=0,0,N21/$N$16) -> 0.14026636 | O28: R$/tc | P28: =IF($O$16=0,0,O21/$O$16) -> 0.14026636 | Q28: R$/tc
D29: SEMANAL | E29: SAFRA | F29: VALOR | G29: SEMANA | H29: SAFRA | I29: SEMANA | J29: SAFRA | K29: META | M29: ETA/CALD. | N29: =IF($N$16=0,0,N22/$N$16) -> 0.47889737 | O29: R$/tc | P29: =IF($O$16=0,0,O22/$O$16) -> 0.47889737 | Q29: R$/tc
B30: CAL VIRGEM | C30: kg | E30: =D30 -> 0 | F30: 1.03 | G30: =D30*F30 -> 0 | H30: =E30*F30 -> 0 | I30: =IF($N$16=0,0,D30/$N$16*1000) -> 0 | J30: =IF($O$16=0,0,E30/$O$16*1000) -> 0 | K30: 0 | M30: TOTAL | N30: =IF($O$16=0,0,O23/$O$16) -> 3.5113802 | O30: R$/tc | P30: =IF($O$16=0,0,O23/$O$16) -> 3.5113802 | Q30: R$/tc
B31: SODA CÁUSTICA | C31: kg | D31: 25 | E31: =D31 -> 25 | F31: 5.83 | G31: =D31*F31 -> 145.75 | H31: =E31*F31 -> 145.75 | I31: =IF($N$16=0,0,D31/$N$16*1000) -> 0.55012351 | J31: =IF($O$16=0,0,E31/$O$16*1000) -> 0.55012351 | K31: 1.5
B32: BAC.QUATERNARIO | C32: kg | D32: 611.77 | E32: =D32 -> 611.77 | F32: 8.99 | G32: =D32*F32 -> 5499.8123 | H32: =E32*F32 -> 5499.8123 | I32: =IF($N$16=0,0,D32/$N$16*1000) -> 13.461962 | J32: =IF($O$16=0,0,E32/$O$16*1000) -> 13.461962 | K32: 8
B33: HELACLOR | C33: kg | E33: =D33 -> 0 | F33: 24 | G33: =D33*F33 -> 0 | H33: =E33*F33 -> 0 | I33: =IF($N$16=0,0,D33/$N$16*1000) -> 0 | J33: =IF($O$16=0,0,E33/$O$16*1000) -> 0 | K33: 0
B34: SODA PENEIRA ROTATIVA | C34: Kg | D34: 50 | E34: =D34 -> 50 | F34: 5.83 | G34: =D34*F34 -> 291.5 | H34: =E34*F34 -> 291.5 | I34: =IF($N$16=0,0,D34/$N$16*1000) -> 1.100247 | J34: =IF($O$16=0,0,E34/$O$16*1000) -> 1.100247 | K34: 2
B35: SODA PENEIRA VIBRATÓRIA | C35: kg | D35: 75 | E35: =D35 -> 75 | F35: 5.83 | G35: =D35*F35 -> 437.25 | H35: =E35*F35 -> 437.25 | I35: =IF($N$16=0,0,D35/$N$16*1000) -> 1.6503705 | J35: =IF($O$16=0,0,E35/$O$16*1000) -> 1.6503705 | K35: 1
B36: ESTEIRA METALICA | C36: kg | E36: =D36 -> 0 | F36: 5.83 | G36: =D36*F36 -> 0 | H36: =E36*F36 -> 0 | I36: =IF($N$16=0,0,D36/$N$16*1000) -> 0 | J36: =IF($O$16=0,0,E36/$O$16*1000) -> 0 | K36: 1
B38: Caldeira / Eta | D38: Consumo | F38: Custos ( R$ ) | I38: Gr/tc
D39: SEMANAL | E39: SAFRA | F39: VALOR | G39: SEMANA | H39: SAFRA | I39: SEMANA | J39: SAFRA | K39: META
B40: SODA CÁUSTICA | C40: kg | D40: 500 | E40: =D40 -> 500 | F40: 5.83 | G40: =D40*F40 -> 2915 | H40: =E40*F40 -> 2915 | I40: =IF($N$16=0,0,D40/$N$16*1000) -> 11.00247 | J40: =IF($O$16=0,0,E40/$O$16*1000) -> 11.00247 | K40: 6
B41: BRW 150 HELAMIN | C41: kg | D41: 250 | E41: =D41 -> 250 | F41: 37.84 | G41: =D41*F41 -> 9460 | H41: =E41*F41 -> 9460 | I41: =IF($N$16=0,0,D41/$N$16*1000) -> 5.5012351 | J41: =IF($O$16=0,0,E41/$O$16*1000) -> 5.5012351 | K41: 3
B42: POLÍMERO | C42: kg | D42: 38.5 | E42: =D42 -> 38.5 | F42: 21 | G42: =D42*F42 -> 808.5 | H42: =E42*F42 -> 808.5 | I42: =IF($N$16=0,0,D42/$N$16*1000) -> 0.84719021 | J42: =IF($O$16=0,0,E42/$O$16*1000) -> 0.84719021 | K42: 0.35
...

Sheet semana 2
B2: SEMANA | E2: CONSUMO DE PRODUTOS QUÍMICOS SAFRA 2025/2026
B3: 2 | C3: SEMANA 20/04/2026 A 26/04/2026
B4: Destilaria | D4: Consumo | F4: Custos( R$ ) | I4: Gr / m³ | M4: Descrição | N4: Semana | O4: Safra 2026 | P4: Safra 2025
D5: SEMANAL | E5: SAFRA | F5: VALOR | G5: SEMANA | H5: SAFRA | I5: SEMANA | J5: SAFRA | K5: META | M5: AÇÚCAR VHP (scs.) | N5: 58909 | O5: ='semana 1'!O5+N5 -> 105378 | P5: 46285
B6: ÁC.SULFURICO | C6: kg | D6: 19787.9 | E6: =SUM('semana 1'!E6+D6) -> 25769.72 | F6: 2.54 | G6: =F6*D6 -> 50261.266 | H6: ='semana 1'!H6+G6 -> 65455.089 | I6: =IF($N$9=0,0,D6/$N$9*1000) -> 8.2354601 | J6: =IF($O$9=0,0,E6/$O$9*1000)*1000 -> 7376.4003 | K6: 9.8 | M6: AÇÚCAR CRISTAL (scs.) | O6: ='semana 1'!O6+N6 -> 0
B7: ANTIBIÓTICO | C7: kg | D7: 40 | E7: =SUM('semana 1'!E7+D7) -> 70 | F7: 599 | G7: =F7*D7 -> 23960 | H7: ='semana 1'!H7+G7 -> 41930 | I7: =IF($N$9=0,0,D7/$N$9*1000)*1000 -> 16.647467 | J7: =IF($O$9=0,0,E7/$O$9*1000)*1000 -> 20.037005 | K7: 6.8 | M7: ETANOL ANIDRO ( L ) | O7: ='semana 1'!O7+N7 -> 0
B8: ANTIESPUMANTE | C8: kg | D8: 1870 | E8: =SUM('semana 1'!E8+D8) -> 3040 | F8: 12.81 | G8: =F8*D8 -> 23954.7 | H8: ='semana 1'!H8+G8 -> 38942.4 | I8: =IF($N$9=0,0,D8/$N$9*1000)*1000 -> 778.26906 | J8: =IF($O$9=0,0,E8/$O$9*1000)*1000 -> 870.17852 | K8: 400 | M8: ETANOL HIDRATADO ( L ) | N8: 2402768 | O8: ='semana 1'!O8+N8 -> 3493536 | P8: 593721
B9: DISPERSANTE | C9: kg | D9: 684.1 | E9: =SUM('semana 1'!E9+D9) -> 806.31 | F9: 25.15 | G9: =F9*D9 -> 17205.115 | H9: ='semana 1'!H9+G9 -> 20278.696 | I9: =IF($N$9=0,0,D9/$N$9*1000)*1000 -> 284.7133 | J9: =IF($O$9=0,0,E9/$O$9*1000)*1000 -> 230.80054 | K9: 200 | M9: ETANOL TOTAL | N9: =SUM(N7:N8) -> 2402768 | O9: =SUM(O7:O8) -> 3493536
B10: NEUT.ALCOOL | C10: kg | E10: =SUM('semana 1'!E10+D10) -> 0 | F10: 10.98 | G10: =F10*D10 -> 0 | H10: ='semana 1'!H10+G10 -> 0 | I10: =IF($N$9=0,0,D10/$N$9*1000)*1000 -> 0 | J10: =IF($O$9=0,0,E10/$O$9*1000)*1000 -> 0 | K10: 10 | M10: AÇUCAR TOTAL | N10: =SUM(N5:N6) -> 58909 | O10: =SUM(O5:O6) -> 105378
B11: NUTRIENTES | C11: kg | D11: 256 | E11: =SUM('semana 1'!E11+D11) -> 2653.34 | F11: 4.13 | G11: =F11*D11 -> 1057.28 | H11: ='semana 1'!H11+G11 -> 10958.294 | I11: =IF($N$9=0,0,D11/$N$9*1000)*1000 -> 106.54379 | J11: =IF($O$9=0,0,E11/$O$9*1000)*1000 -> 759.49983
B12: SODA CÁUSTICA | C12: kg | D12: 1200 | E12: =SUM('semana 1'!E12+D12) -> 1500 | F12: 5.83 | G12: =F12*D12 -> 6996 | H12: ='semana 1'!H12+G12 -> 8745 | I12: =IF($N$9=0,0,D12/$N$9*1000)*1000 -> 499.424 | J12: =IF($O$9=0,0,E12/$O$9*1000)*1000 -> 429.3644 | K12: 400 | M12: MOAGEM ( Toneladas )
B13: FERMAPLUS | C13: kg | D13: 290.01 | E13: =SUM('semana 1'!E13+D13) -> 290.01 | F13: 6 | G13: =F13*D13 -> 1740.06 | H13: ='semana 1'!H13+G13 -> 1740.06 | I13: =IF($N$9=0,0,D13/$N$9*1000)*1000 -> 120.69829 | J13: =IF($O$9=0,0,E13/$O$9*1000)*1000 -> 83.013314 | K13: 500 | M13: CANA MOÍDA | N13: SEMANA | O13: SAFRA 2026 | P13: SAFRA 2025
B14: MONENSINA | C14: kg | D14: 15 | E14: =SUM('semana 1'!E14+D14) -> 15 | F14: 425 | G14: =F14*D14 -> 6375 | H14: ='semana 1'!H14+G14 -> 6375 | I14: =IF($N$9=0,0,D14/$N$9*1000)*1000 -> 6.2428 | J14: =IF($O$9=0,0,E14/$O$9*1000)*1000 -> 4.293644 | K14: 3 | M14: PARA ETANOL | N14: 32779.661 | O14: ='semana 1'!O14+'semana 2'!N14 -> 52127.708 | P14: 17596.294
M15: PARA AÇÚCAR | N15: 24180.939 | O15: ='semana 1'!O15+'semana 2'!N15 -> 50277.232 | P15: 32677.166
B16: Fábrica | D16: Consumo | F16: Custos( R$ ) | I16: Gr / tc | M16: MOÍDA TOTAL | N16: =SUM(N14:N15) -> 56960.6 | O16: =SUM(O14:O15) -> 102404.94 | P16: =P15+P14 -> 50273.46
D17: SEMANAL | E17: SAFRA | F17: VALOR | G17: SEMANA | H17: SAFRA | I17: SEMANA | J17: SAFRA | K17: META
B18: FLOCULANTE | C18: kg | D18: 350 | E18: ='semana 1'!E18+D18 -> 725 | F18: 21 | G18: =D18*F18 -> 7350 | H18: ='semana 1'!H18+G18 -> 15225 | I18: =IF($N$10=0,0,D18/$N$16*1000) -> 6.1445982 | J18: =IF($O$10=0,0,E18/$O$16*1000) -> 7.0797366 | K18: 6.1 | M18: SETOR | N18: SEMANA | O18: SAFRA 2025
B19: FLOCUL. FILTRO | C19: kg | D19: 350 | E19: ='semana 1'!E19+D19 -> 675 | F19: 15.63 | G19: =D19*F19 -> 5470.5 | H19: ='semana 1'!H19+G19 -> 10550.25 | I19: =IF($N$10=0,0,D19/$N$16*1000) -> 6.1445982 | J19: =IF($O$10=0,0,E19/$O$16*1000) -> 6.5914789 | K19: 9 | M19: DESTILARIA | N19: =SUM(G6:G14) -> 131549.42 | O19: =SUM(H6:H14) -> 194424.54
B20: ENXOFRE | C20: kg | E20: ='semana 1'!E20+D20 -> 1000 | F20: 6.7 | G20: =D20*F20 -> 0 | H20: ='semana 1'!H20+G20 -> 6700 | I20: =IF($N$10=0,0,D20/$N$16*1000) -> 0 | J20: =IF($O$10=0,0,E20/$O$16*1000) -> 9.7651539 | K20: 51 | M20: FÁBRICA | N20: =SUM(G18:G27) -> 69084.746 | O20: =SUM(H18:H27) -> 137644.5
B21: AC.FOSFÓRICO | C21: kg | E21: ='semana 1'!E21+D21 -> 0 | F21: 5.85 | G21: =D21*F21 -> 0 | H21: ='semana 1'!H21+G21 -> 0 | I21: =IF($N$10=0,0,D21/$N$16*1000) -> 0 | J21: =IF($O$10=0,0,E21/$O$16*1000) -> 0 | M21: MOENDA | N21: =SUM(G30:G36) -> 7220.3612 | O21: =SUM(H30:H36) -> 13594.674
B22: CAL DOLOMÍTICA | C22: kg | D22: 32296 | E22: ='semana 1'!E22+D22 -> 66296 | F22: 1.03 | G22: =D22*F22 -> 33264.88 | H22: ='semana 1'!H22+G22 -> 68284.88 | I22: =IF($N$10=0,0,D22/$N$16*1000) -> 566.98841 | J22: =IF($O$10=0,0,E22/$O$16*1000) -> 647.39064 | K22: 1000 | M22: ETA/CALD. | N22: =SUM(G40:G51) -> 15585.747 | O22: =SUM(H40:H51) -> 37348.922
B23: SODA CÁUSTICA | C23: kg | D23: 775 | E23: ='semana 1'!E23+D23 -> 1350 | F23: 5.83 | G23: =D23*F23 -> 4518.25 | H23: ='semana 1'!H23+G23 -> 7870.5 | I23: =IF($N$10=0,0,D23/$N$16*1000) -> 13.605896 | J23: =IF($O$10=0,0,E23/$O$16*1000) -> 13.182958 | K23: 13 | M23: CUSTO TOTAL (R$ ) | N23: =SUM(N19:N22) -> 223440.28 | O23: =SUM(O19:O22) -> 383012.63
B24: NEUT.VAPOR | C24: kg | D24: 663.54 | E24: ='semana 1'!E24+D24 -> 1090.59 | F24: 8 | G24: =D24*F24 -> 5308.32 | H24: ='semana 1'!H24+G24 -> 8724.72 | I24: =IF($N$10=0,0,D24/$N$16*1000) -> 11.649105 | J24: =IF($O$10=0,0,E24/$O$16*1000) -> 10.649779 | K24: 2.8
B25: ANTI-INCRUST. | C25: kg | D25: 2251.76 | E25: ='semana 1'!E25+D25 -> 3468.23 | F25: 5.85 | G25: =D25*F25 -> 13172.796 | H25: ='semana 1'!H25+G25 -> 20289.145 | I25: =IF($N$10=0,0,D25/$N$16*1000) -> 39.531887 | J25: =IF($O$10=0,0,E25/$O$16*1000) -> 33.8678 | K25: 28 | M25: Setor | N25: Semana | P25: Safra 2025
B26: CLARIFICANTE FL 40 | C26: Kg | E26: ='semana 1'!E26+D26 -> 0 | F26: 6.98 | G26: =D26*F26 -> 0 | H26: ='semana 1'!H26+G26 -> 0 | I26: =IF($N$10=0,0,D26/$N$16*1000) -> 0 | J26: =IF($O$10=0,0,E26/$O$16*1000) -> 0 | K26: 21.3 | M26: DESTILARIA | N26: =IF($N$9=0,0,N19/$N$9*1000) -> 54.749115 | O26: R$/m³ | P26: =IF($O$9=0,0,O19/$O$9*1000) -> 55.652651 | Q26: R$/m³
B27: LUBRIFICANTE MASSA | C27: Kg | E27: ='semana 1'!E27+D27 -> 0 | G27: =D27*F27 -> 0 | H27: ='semana 1'!H27+G27 -> 0 | I27: =IF($N$10=0,0,D27/$N$16*1000) -> 0 | J27: =IF($O$10=0,0,E27/$O$16*1000) -> 0 | K27: 3.6 | M27: FÁBRICA | N27: =IF($N$10=0,0,N20/$N$16) -> 1.2128514 | O27: R$/tc | P27: =IF($O$10=0,0,O20/$O$16) -> 1.3441197 | Q27: R$/tc
B28: Moenda | D28: Consumo | F28: Custos( R$ ) | I28: Gr / tc | M28: MOENDA | N28: =IF($N$16=0,0,N21/$N$16) -> 0.12676062 | O28: R$/tc | P28: =IF($O$16=0,0,O21/$O$16) -> 0.13275408 | Q28: R$/tc
D29: SEMANAL | E29: SAFRA | F29: VALOR | G29: SEMANA | H29: SAFRA | I29: SEMANA | J29: SAFRA | K29: META | M29: ETA/CALD. | N29: =IF($N$16=0,0,N22/$N$16) -> 0.27362329 | O29: R$/tc | P29: =IF($O$16=0,0,O22/$O$16) -> 0.36471797 | Q29: R$/tc
B30: CAL VIRGEM | C30: kg | E30: ='semana 1'!E30+D30 -> 0 | F30: 1.03 | G30: =D30*F30 -> 0 | H30: =E30*F30 -> 0 | I30: =IF($N$16=0,0,D30/$N$16*1000) -> 0 | J30: =IF($O$16=0,0,E30/$O$16*1000) -> 0 | K30: 0 | M30: TOTAL | N30: =IF($N$16=0,0,N23/$N$16) -> 3.9227163 | O30: R$/tc | P30: =IF($O$16=0,0,O23/$O$16) -> 3.7401773 | Q30: R$/tc
B31: SODA CÁUSTICA | C31: kg | E31: ='semana 1'!E31+D31 -> 25 | F31: 5.83 | G31: =D31*F31 -> 0 | H31: =E31*F31 -> 145.75 | I31: =IF($N$16=0,0,D31/$N$16*1000) -> 0 | J31: =IF($O$16=0,0,E31/$O$16*1000) -> 0.24412885 | K31: 1.5
B32: BAC.QUATERNARIO | C32: kg | D32: 705.88 | E32: ='semana 1'!E32+D32 -> 1317.65 | F32: 8.99 | G32: =D32*F32 -> 6345.8612 | H32: =E32*F32 -> 11845.674 | I32: =IF($N$16=0,0,D32/$N$16*1000) -> 12.392426 | J32: =IF($O$16=0,0,E32/$O$16*1000) -> 12.867055 | K32: 8
B33: HELACLOR | C33: kg | E33: ='semana 1'!E33+D33 -> 0 | F33: 24 | G33: =D33*F33 -> 0 | H33: =E33*F33 -> 0 | I33: =IF($N$16=0,0,D33/$N$16*1000) -> 0 | J33: =IF($O$16=0,0,E33/$O$16*1000) -> 0 | K33: 0
B34: SODA PENEIRA ROTATIVA | C34: Kg | D34: 100 | E34: ='semana 1'!E34+D34 -> 150 | F34: 5.83 | G34: =D34*F34 -> 583 | H34: =E34*F34 -> 874.5 | I34: =IF($N$16=0,0,D34/$N$16*1000) -> 1.7555995 | J34: =IF($O$16=0,0,E34/$O$16*1000) -> 1.4647731 | K34: 2
B35: SODA PENEIRA VIBRATÓRIA | C35: kg | D35: 50 | E35: ='semana 1'!E35+D35 -> 125 | F35: 5.83 | G35: =D35*F35 -> 291.5 | H35: =E35*F35 -> 728.75 | I35: =IF($N$16=0,0,D35/$N$16*1000) -> 0.87779974 | J35: =IF($O$16=0,0,E35/$O$16*1000) -> 1.2206442 | K35: 1
B36: ESTEIRA METALICA | C36: kg | E36: ='semana 1'!E36+D36 -> 0 | F36: 5.83 | G36: =D36*F36 -> 0 | H36: =E36*F36 -> 0 | I36: =IF($N$16=0,0,D36/$N$16*1000) -> 0 | J36: =IF($O$16=0,0,E36/$O$16*1000) -> 0 | K36: 1
B38: Caldeira / Eta | D38: Consumo | F38: Custos ( R$ ) | I38: Gr/tc
D39: SEMANAL | E39: SAFRA | F39: VALOR | G39: SEMANA | H39: SAFRA | I39: SEMANA | J39: SAFRA | K39: META
B40: SODA CÁUSTICA | C40: kg | D40: 175 | E40: ='semana 1'!E40+D40 -> 675 | F40: 5.83 | G40: =D40*F40 -> 1020.25 | H40: =E40*F40 -> 3935.25 | I40: =IF($N$16=0,0,D40/$N$16*1000) -> 3.0722991 | J40: =IF($O$16=0,0,E40/$O$16*1000) -> 6.5914789 | K40: 6
B41: BRW 150 HELAMIN | C41: kg | D41: 150 | E41: ='semana 1'!E41+D41 -> 400 | F41: 37.84 | G41: =D41*F41 -> 5676 | H41: =E41*F41 -> 15136 | I41: =IF($N$16=0,0,D41/$N$16*1000) -> 2.6333992 | J41: =IF($O$16=0,0,E41/$O$16*1000) -> 3.9060616 | K41: 3
B42: POLÍMERO | C42: kg | E42: ='semana 1'!E42+D42 -> 38.5 | F42: 21 | G42: =D42*F42 -> 0 | H42: =E42*F42 -> 808.5 | I42: =IF($N$16=0,0,D42/$N$16*1000) -> 0 | J42: =IF($O$16=0,0,E42/$O$16*1000) -> 0.37595843 | K42: 0.35
...

Sheet semana 3
B2: SEMANA | E2: CONSUMO DE PRODUTOS QUÍMICOS SAFRA 2026/2027 | S2: SEMANA 2
B3: 3 | C3: SEMANA 27/04/2026 A 03/05/2026
B4: Destilaria | D4: Consumo | F4: Custos( R$ ) | I4: Gr / m³ | M4: Descrição | N4: Semana | O4: Safra 2025 | P4: Safra 2024
D5: SEMANAL | E5: SAFRA | F5: VALOR | G5: SEMANA | H5: SAFRA | I5: SEMANA | J5: SAFRA | K5: META | M5: AÇÚCAR VHP (scs.) | N5: 61456 | O5: =INDIRECT("'" & $S$2 & "'!O" & ROW()) + N5 -> 166834 | P5: 109459
B6: ÁC.SULFURICO | C6: kg | D6: 8459.22 | E6: =INDIRECT("'" & $S$2 & "'!E" & ROW()) + D6 -> 34228.94 | F6: 2.54 | G6: =F6*D6 -> 21486.419 | H6: =INDIRECT("'" & $S$2 & "'!H" & ROW()) + G6 -> 86941.508 | I6: =IF($N$9=0,0,D6/$N$9*1000) -> 3.264006 | J6: =IF($O$9=0,0,E6/$O$9*1000) -> 5.6249454 | K6: 9.8 | M6: AÇÚCAR CRISTAL (scs.) | O6: ='semana 1'!O6+N6 -> 0
B7: ANTIBIÓTICO | C7: kg | E7: =INDIRECT("'" & $S$2 & "'!E" & ROW()) + D7 -> 70 | F7: 599 | G7: =F7*D7 -> 0 | H7: =INDIRECT("'" & $S$2 & "'!H" & ROW()) + G7 -> 41930 | I7: =IF($N$9=0,0,D7/$N$9*1000)*1000 -> 0 | J7: =IF($O$9=0,0,E7/$O$9*1000)*1000 -> 11.503312 | K7: 6.8 | M7: ETANOL ANIDRO ( L ) | O7: ='semana 1'!O7+N7 -> 0
B8: ANTIESPUMANTE | C8: kg | D8: 2520 | E8: =INDIRECT("'" & $S$2 & "'!E" & ROW()) + D8 -> 5560 | F8: 15 | G8: =F8*D8 -> 37800 | H8: =INDIRECT("'" & $S$2 & "'!H" & ROW()) + G8 -> 76742.4 | I8: =IF($N$9=0,0,D8/$N$9*1000)*1000 -> 972.34677 | J8: =IF($O$9=0,0,E8/$O$9*1000)*1000 -> 913.69164 | K8: 400 | M8: ETANOL HIDRATADO ( L ) | N8: 2591668 | O8: =INDIRECT("'" & $S$2 & "'!O" & ROW()) + N8 -> 6085204 | P8: 1891659
B9: DISPERSANTE | C9: kg | D9: 1445.67 | E9: =INDIRECT("'" & $S$2 & "'!E" & ROW()) + D9 -> 2251.98 | F9: 25.15 | G9: =F9*D9 -> 36358.601 | H9: =INDIRECT("'" & $S$2 & "'!H" & ROW()) + G9 -> 56637.297 | I9: =IF($N$9=0,0,D9/$N$9*1000)*1000 -> 557.8145 | J9: =IF($O$9=0,0,E9/$O$9*1000)*1000 -> 370.07469 | K9: 200 | M9: ETANOL TOTAL | N9: =SUM(N7:N8) -> 2591668 | O9: =SUM(O7:O8) -> 6085204
B10: NEUT.ALCOOL | C10: kg | D10: 50 | E10: =INDIRECT("'" & $S$2 & "'!E" & ROW()) + D10 -> 50 | F10: 10.98 | G10: =F10*D10 -> 549 | H10: =INDIRECT("'" & $S$2 & "'!H" & ROW()) + G10 -> 549 | I10: =IF($N$9=0,0,D10/$N$9*1000)*1000 -> 19.292595 | J10: =IF($O$9=0,0,E10/$O$9*1000)*1000 -> 8.2166514 | K10: 10 | M10: AÇUCAR TOTAL | N10: =SUM(N5:N6) -> 61456 | O10: =SUM(O5:O6) -> 166834
B11: NUTRIENTES | C11: kg | E11: =INDIRECT("'" & $S$2 & "'!E" & ROW()) + D11 -> 2653.34 | F11: 4.13 | G11: =F11*D11 -> 0 | H11: =INDIRECT("'" & $S$2 & "'!H" & ROW()) + G11 -> 10958.294 | I11: =IF($N$9=0,0,D11/$N$9*1000)*1000 -> 0 | J11: =IF($O$9=0,0,E11/$O$9*1000)*1000 -> 436.0314
B12: SODA CÁUSTICA | C12: kg | D12: 725 | E12: =INDIRECT("'" & $S$2 & "'!E" & ROW()) + D12 -> 2225 | F12: 5.83 | G12: =F12*D12 -> 4226.75 | H12: =INDIRECT("'" & $S$2 & "'!H" & ROW()) + G12 -> 12971.75 | I12: =IF($N$9=0,0,D12/$N$9*1000)*1000 -> 279.74262 | J12: =IF($O$9=0,0,E12/$O$9*1000)*1000 -> 365.64099 | K12: 400 | M12: MOAGEM ( Toneladas )
B13: FERMAPLUS | C13: kg | D13: 580 | E13: =INDIRECT("'" & $S$2 & "'!E" & ROW()) + D13 -> 870.01 | F13: 6 | G13: =F13*D13 -> 3480 | H13: =INDIRECT("'" & $S$2 & "'!H" & ROW()) + G13 -> 5220.06 | I13: =IF($N$9=0,0,D13/$N$9*1000)*1000 -> 223.7941 | J13: =IF($O$9=0,0,E13/$O$9*1000)*1000 -> 142.97138 | K13: 500 | M13: CANA MOÍDA | N13: SEMANA | O13: SAFRA 2025 | P13: SAFRA 2024
B14: MONENSINA | C14: kg | E14: =INDIRECT("'" & $S$2 & "'!E" & ROW()) + D14 -> 15 | F14: 425 | G14: =F14*D14 -> 0 | H14: =INDIRECT("'" & $S$2 & "'!H" & ROW()) + G14 -> 6375 | I14: =IF($N$9=0,0,D14/$N$9*1000)*1000 -> 0 | J14: =IF($O$9=0,0,E14/$O$9*1000)*1000 -> 2.4649954 | K14: 3 | M14: PARA ETANOL | N14: 34518.719 | O14: =INDIRECT("'" & $S$2 & "'!O" & ROW()) + N14 -> 86646.427 | P14: 35394.24
M15: PARA AÇÚCAR | N15: 24985.721 | O15: =INDIRECT("'" & $S$2 & "'!O" & ROW()) + N15 -> 75262.953 | P15: 58637.28
B16: Fábrica | D16: Consumo | F16: Custos( R$ ) | I16: Gr / tc | M16: MOÍDA TOTAL | N16: =SUM(N14:N15) -> 59504.44 | O16: =SUM(O14:O15) -> 161909.38 | P16: =P15+P14 -> 94031.52
D17: SEMANAL | E17: SAFRA | F17: VALOR | G17: SEMANA | H17: SAFRA | I17: SEMANA | J17: SAFRA | K17: META
B18: FLOCULANTE | C18: kg | D18: 325 | E18: =INDIRECT("'" & $S$2 & "'!E" & ROW()) + D18 -> 1050 | F18: 21 | G18: =D18*F18 -> 6825 | H18: =INDIRECT("'" & $S$2 & "'!H" & ROW()) + G18 -> 22050 | I18: =IF($N$10=0,0,D18/$N$16*1000) -> 5.4617773 | J18: =IF($O$10=0,0,E18/$O$16*1000) -> 6.4851091 | K18: 6.1 | M18: SETOR | N18: SEMANA | O18: SAFRA 2025
B19: FLOCUL. FILTRO | C19: kg | D19: 425 | E19: =INDIRECT("'" & $S$2 & "'!E" & ROW()) + D19 -> 1100 | F19: 15.63 | G19: =D19*F19 -> 6642.75 | H19: =INDIRECT("'" & $S$2 & "'!H" & ROW()) + G19 -> 17193 | I19: =IF($N$10=0,0,D19/$N$16*1000) -> 7.1423242 | J19: =IF($O$10=0,0,E19/$O$16*1000) -> 6.7939239 | K19: 9 | M19: DESTILARIA | N19: =SUM(G6:G14) -> 103900.77 | O19: =INDIRECT("'" & $S$2 & "'!O" & ROW()) + N19 -> 298325.31
B20: ENXOFRE | C20: kg | E20: =INDIRECT("'" & $S$2 & "'!E" & ROW()) + D20 -> 1000 | F20: 6.7 | G20: =D20*F20 -> 0 | H20: =INDIRECT("'" & $S$2 & "'!H" & ROW()) + G20 -> 6700 | I20: =IF($N$10=0,0,D20/$N$16*1000) -> 0 | J20: =IF($O$10=0,0,E20/$O$16*1000) -> 6.1762944 | K20: 51 | M20: FÁBRICA | N20: =SUM(G18:G27)+G51 -> 66002.84 | O20: =INDIRECT("'" & $S$2 & "'!O" & ROW()) + N20 -> 203647.34
B21: AC.FOSFÓRICO | C21: kg | E21: =INDIRECT("'" & $S$2 & "'!E" & ROW()) + D21 -> 0 | F21: 5.85 | G21: =D21*F21 -> 0 | H21: =INDIRECT("'" & $S$2 & "'!H" & ROW()) + G21 -> 0 | I21: =IF($N$10=0,0,D21/$N$16*1000) -> 0 | J21: =IF($O$10=0,0,E21/$O$16*1000) -> 0 | M21: MOENDA | N21: =SUM(G30:G37) -> 8267.8052 | O21: =INDIRECT("'" & $S$2 & "'!O" & ROW()) + N21 -> 21862.479
B22: CAL DOLOMÍTICA | C22: kg | D22: 26296.6 | E22: =INDIRECT("'" & $S$2 & "'!E" & ROW()) + D22 -> 92592.6 | F22: 1.03 | G22: =D22*F22 -> 27085.498 | H22: =INDIRECT("'" & $S$2 & "'!H" & ROW()) + G22 -> 95370.378 | I22: =IF($N$10=0,0,D22/$N$16*1000) -> 441.92669 | J22: =IF($O$10=0,0,E22/$O$16*1000) -> 571.87916 | K22: 1000 | M22: ETA/CALD. | N22: =SUM(G40:G53)-G51 -> 13355.406 | O22: =INDIRECT("'" & $S$2 & "'!O" & ROW()) + N22 -> 50704.328
B23: SODA CÁUSTICA | C23: kg | D23: 600 | E23: =INDIRECT("'" & $S$2 & "'!E" & ROW()) + D23 -> 1950 | F23: 5.83 | G23: =D23*F23 -> 3498 | H23: =INDIRECT("'" & $S$2 & "'!H" & ROW()) + G23 -> 11368.5 | I23: =IF($N$10=0,0,D23/$N$16*1000) -> 10.083281 | J23: =IF($O$10=0,0,E23/$O$16*1000) -> 12.043774 | K23: 13 | M23: CUSTO TOTAL (R$ ) | N23: =SUM(N19:N22) -> 191526.82 | O23: =SUM(O19:O22) -> 574539.45
B24: NEUT.VAPOR | C24: kg | D24: 1239.41 | E24: =INDIRECT("'" & $S$2 & "'!E" & ROW()) + D24 -> 2330 | F24: 8 | G24: =D24*F24 -> 9915.28 | H24: =INDIRECT("'" & $S$2 & "'!H" & ROW()) + G24 -> 18640 | I24: =IF($N$10=0,0,D24/$N$16*1000) -> 20.828866 | J24: =IF($O$10=0,0,E24/$O$16*1000) -> 14.390766 | K24: 2.8
B25: ANTI-INCRUST. | C25: kg | D25: 1863.52 | E25: =INDIRECT("'" & $S$2 & "'!E" & ROW()) + D25 -> 5331.75 | F25: 5.85 | G25: =D25*F25 -> 10901.592 | H25: =INDIRECT("'" & $S$2 & "'!H" & ROW()) + G25 -> 31190.737 | I25: =IF($N$10=0,0,D25/$N$16*1000) -> 31.317327 | J25: =IF($O$10=0,0,E25/$O$16*1000) -> 32.930458 | K25: 28 | M25: Setor | N25: Semana | P25: Safra 2025
B26: CLARIFICANTE FL 40 | C26: Kg | E26: =INDIRECT("'" & $S$2 & "'!E" & ROW()) + D26 -> 0 | F26: 6.98 | G26: =D26*F26 -> 0 | H26: =INDIRECT("'" & $S$2 & "'!H" & ROW()) + G26 -> 0 | I26: =IF($N$10=0,0,D26/$N$16*1000) -> 0 | J26: =IF($O$10=0,0,E26/$O$16*1000) -> 0 | K26: 21.3 | M26: DESTILARIA | N26: =IF($N$9=0,0,N19/$N$9*1000) -> 40.090308 | O26: R$/m³ | P26: =IF($O$9=0,0,O19/$O$9*1000) -> 49.024701 | Q26: R$/m³
B27: LUBRIFICANTE MASSA | C27: Kg | E27: =INDIRECT("'" & $S$2 & "'!E" & ROW()) + D27 -> 0 | G27: =D27*F27 -> 0 | H27: =INDIRECT("'" & $S$2 & "'!H" & ROW()) + G27 -> 0 | I27: =IF($N$10=0,0,D27/$N$16*1000) -> 0 | J27: =IF($O$10=0,0,E27/$O$16*1000) -> 0 | K27: 3.6 | M27: FÁBRICA | N27: =IF($N$10=0,0,N20/$N$16) -> 1.1092087 | O27: R$/tc | P27: =IF($O$10=0,0,O20/$O$16) -> 1.2577859 | Q27: R$/tc
B28: Moenda | D28: Consumo | F28: Custos( R$ ) | I28: Gr / tc | M28: MOENDA | N28: =IF($N$16=0,0,N21/$N$16) -> 0.13894434 | O28: R$/tc | P28: =IF($O$16=0,0,O21/$O$16) -> 0.13502911 | Q28: R$/tc
D29: SEMANAL | E29: SAFRA | F29: VALOR | G29: SEMANA | H29: SAFRA | I29: SEMANA | J29: SAFRA | K29: META | M29: ETA/CALD. | N29: =IF($N$16=0,0,N22/$N$16) -> 0.22444386 | O29: R$/tc | P29: =IF($O$16=0,0,O22/$O$16) -> 0.31316486 | Q29: R$/tc
B30: CAL VIRGEM | C30: kg | E30: =INDIRECT("'" & $S$2 & "'!E" & ROW()) + D30 -> 0 | F30: 1.03 | G30: =D30*F30 -> 0 | H30: =INDIRECT("'" & $S$2 & "'!H" & ROW()) + G30 -> 0 | I30: =IF($N$16=0,0,D30/$N$16*1000) -> 0 | J30: =IF($O$16=0,0,E30/$O$16*1000) -> 0 | K30: 0 | M30: TOTAL | N30: =IF($N$16=0,0,N23/$N$16) -> 3.218698 | O30: R$/tc | P30: =IF($O$16=0,0,O23/$O$16) -> 3.5485248 | Q30: R$/tc
B31: SODA CÁUSTICA | C31: kg | D31: 50 | E31: =INDIRECT("'" & $S$2 & "'!E" & ROW()) + D31 -> 75 | F31: 5.83 | G31: =D31*F31 -> 291.5 | H31: =INDIRECT("'" & $S$2 & "'!H" & ROW()) + G31 -> 437.25 | I31: =IF($N$16=0,0,D31/$N$16*1000) -> 0.84027343 | J31: =IF($O$16=0,0,E31/$O$16*1000) -> 0.46322208 | K31: 1.5
B32: BAC.QUATERNARIO | C32: kg | D32: 676.48 | E32: =INDIRECT("'" & $S$2 & "'!E" & ROW()) + D32 -> 1994.13 | F32: 8.99 | G32: =D32*F32 -> 6081.5552 | H32: =INDIRECT("'" & $S$2 & "'!H" & ROW()) + G32 -> 17927.229 | I32: =IF($N$16=0,0,D32/$N$16*1000) -> 11.368563 | J32: =IF($O$16=0,0,E32/$O$16*1000) -> 12.316334 | K32: 8
B33: HELACLOR | C33: kg | E33: =INDIRECT("'" & $S$2 & "'!E" & ROW()) + D33 -> 0 | F33: 24 | G33: =D33*F33 -> 0 | H33: =INDIRECT("'" & $S$2 & "'!H" & ROW()) + G33 -> 0 | I33: =IF($N$16=0,0,D33/$N$16*1000) -> 0 | J33: =IF($O$16=0,0,E33/$O$16*1000) -> 0 | K33: 0
B34: SODA PENEIRA ROTATIVA | C34: Kg | D34: 200 | E34: =INDIRECT("'" & $S$2 & "'!E" & ROW()) + D34 -> 350 | F34: 5.83 | G34: =D34*F34 -> 1166 | H34: =INDIRECT("'" & $S$2 & "'!H" & ROW()) + G34 -> 2040.5 | I34: =IF($N$16=0,0,D34/$N$16*1000) -> 3.3610937 | J34: =IF($O$16=0,0,E34/$O$16*1000) -> 2.161703 | K34: 2
B35: SODA PENEIRA VIBRATÓRIA | C35: kg | D35: 125 | E35: =INDIRECT("'" & $S$2 & "'!E" & ROW()) + D35 -> 250 | F35: 5.83 | G35: =D35*F35 -> 728.75 | H35: =INDIRECT("'" & $S$2 & "'!H" & ROW()) + G35 -> 1457.5 | I35: =IF($N$16=0,0,D35/$N$16*1000) -> 2.1006836 | J35: =IF($O$16=0,0,E35/$O$16*1000) -> 1.5440736 | K35: 1
B36: ESTEIRA METALICA | C36: kg | E36: =INDIRECT("'" & $S$2 & "'!E" & ROW()) + D36 -> 0 | F36: 5.83 | G36: =D36*F36 -> 0 | H36: =INDIRECT("'" & $S$2 & "'!H" & ROW()) + G36 -> 0 | I36: =IF($N$16=0,0,D36/$N$16*1000) -> 0 | J36: =IF($O$16=0,0,E36/$O$16*1000) -> 0 | K36: 1
B38: Caldeira / Eta | D38: Consumo | F38: Custos ( R$ ) | I38: Gr/tc
D39: SEMANAL | E39: SAFRA | F39: VALOR | G39: SEMANA | H39: SAFRA | I39: SEMANA | J39: SAFRA | K39: META
B40: SODA CÁUSTICA | C40: kg | E40: =INDIRECT("'" & $S$2 & "'!E" & ROW()) + D40 -> 675 | F40: 5.83 | G40: =D40*F40 -> 0 | H40: =INDIRECT("'" & $S$2 & "'!H" & ROW()) + G40 -> 3935.25 | I40: =IF($N$16=0,0,D40/$N$16*1000) -> 0 | J40: =IF($O$16=0,0,E40/$O$16*1000) -> 4.1689987 | K40: 6
B41: BRW 150 HELAMIN | C41: kg | D41: 150 | E41: =INDIRECT("'" & $S$2 & "'!E" & ROW()) + D41 -> 550 | F41: 37.84 | G41: =D41*F41 -> 5676 | H41: =INDIRECT("'" & $S$2 & "'!H" & ROW()) + G41 -> 20812 | I41: =IF($N$16=0,0,D41/$N$16*1000) -> 2.5208203 | J41: =IF($O$16=0,0,E41/$O$16*1000) -> 3.3969619 | K41: 3
B42: POLÍMERO | C42: kg | E42: =INDIRECT("'" & $S$2 & "'!E" & ROW()) + D42 -> 38.5 | F42: 21 | G42: =D42*F42 -> 0 | H42: =INDIRECT("'" & $S$2 & "'!H" & ROW()) + G42 -> 808.5 | I42: =IF($N$16=0,0,D42/$N$16*1000) -> 0 | J42: =IF($O$16=0,0,E42/$O$16*1000) -> 0.23778734 | K42: 0.35
...

Sheet semana 4
B2: SEMANA | E2: CONSUMO DE PRODUTOS QUÍMICOS SAFRA 2026/2027 | S2: SEMANA 3
B3: 4 | C3: SEMANA 04/05/2026 A 10/05/2026
B4: Destilaria | D4: Consumo | F4: Custos( R$ ) | I4: Gr / m³ | M4: Descrição | N4: Semana | O4: Safra 2025 | P4: Safra 2025
D5: SEMANAL | E5: SAFRA | F5: VALOR | G5: SEMANA | H5: SAFRA | I5: SEMANA | J5: SAFRA | K5: META | M5: AÇÚCAR VHP (scs.) | N5: 76824 | O5: =INDIRECT("'" & $S$2 & "'!O" & ROW()) + N5 -> 243658 | P5: 162359
B6: ÁC.SULFURICO | C6: kg | D6: 12096.2 | E6: =INDIRECT("'" & $S$2 & "'!E" & ROW()) + D6 -> 46325.14 | F6: 2.54 | G6: =F6*D6 -> 30724.348 | H6: =INDIRECT("'" & $S$2 & "'!H" & ROW()) + G6 -> 117665.86 | I6: =IF($N$9=0,0,D6/$N$9*1000) -> 4.3326873 | J6: =IF($O$9=0,0,E6/$O$9*1000) -> 5.2185281 | K6: 9.8 | M6: AÇÚCAR CRISTAL (scs.) | O6: ='semana 1'!O6+N6 -> 0
B7: ANTIBIÓTICO | C7: kg | E7: =INDIRECT("'" & $S$2 & "'!E" & ROW()) + D7 -> 70 | F7: 599 | G7: =F7*D7 -> 0 | H7: =INDIRECT("'" & $S$2 & "'!H" & ROW()) + G7 -> 41930 | I7: =IF($N$9=0,0,D7/$N$9*1000)*1000 -> 0 | J7: =IF($O$9=0,0,E7/$O$9*1000)*1000 -> 7.8855016 | K7: 6.8 | M7: ETANOL ANIDRO ( L ) | O7: ='semana 1'!O7+N7 -> 0
B8: ANTIESPUMANTE | C8: kg | D8: 1745 | E8: =INDIRECT("'" & $S$2 & "'!E" & ROW()) + D8 -> 7305 | F8: 15 | G8: =F8*D8 -> 26175 | H8: =INDIRECT("'" & $S$2 & "'!H" & ROW()) + G8 -> 102917.4 | I8: =IF($N$9=0,0,D8/$N$9*1000)*1000 -> 625.03425 | J8: =IF($O$9=0,0,E8/$O$9*1000)*1000 -> 822.90842 | K8: 400 | M8: ETANOL HIDRATADO ( L ) | N8: 2791847 | O8: =INDIRECT("'" & $S$2 & "'!O" & ROW()) + N8 -> 8877051 | P8: 2979314
B9: DISPERSANTE | C9: kg | D9: 1264.71 | E9: =INDIRECT("'" & $S$2 & "'!E" & ROW()) + D9 -> 3516.69 | F9: 25.15 | G9: =F9*D9 -> 31807.457 | H9: =INDIRECT("'" & $S$2 & "'!H" & ROW()) + G9 -> 88444.753 | I9: =IF($N$9=0,0,D9/$N$9*1000)*1000 -> 453.00119 | J9: =IF($O$9=0,0,E9/$O$9*1000)*1000 -> 396.15521 | K9: 200 | M9: ETANOL TOTAL | N9: =SUM(N7:N8) -> 2791847 | O9: =SUM(O7:O8) -> 8877051
B10: NEUT.ALCOOL | C10: kg | D10: 50 | E10: =INDIRECT("'" & $S$2 & "'!E" & ROW()) + D10 -> 100 | F10: 10.98 | G10: =F10*D10 -> 549 | H10: =INDIRECT("'" & $S$2 & "'!H" & ROW()) + G10 -> 1098 | I10: =IF($N$9=0,0,D10/$N$9*1000)*1000 -> 17.909291 | J10: =IF($O$9=0,0,E10/$O$9*1000)*1000 -> 11.265002 | K10: 10 | M10: AÇUCAR TOTAL | N10: =SUM(N5:N6) -> 76824 | O10: =SUM(O5:O6) -> 243658
B11: NUTRIENTES | C11: kg | E11: =INDIRECT("'" & $S$2 & "'!E" & ROW()) + D11 -> 2653.34 | F11: 4.13 | G11: =F11*D11 -> 0 | H11: =INDIRECT("'" & $S$2 & "'!H" & ROW()) + G11 -> 10958.294 | I11: =IF($N$9=0,0,D11/$N$9*1000)*1000 -> 0 | J11: =IF($O$9=0,0,E11/$O$9*1000)*1000 -> 298.89881
B12: SODA CÁUSTICA | C12: kg | D12: 775 | E12: =INDIRECT("'" & $S$2 & "'!E" & ROW()) + D12 -> 3000 | F12: 5.83 | G12: =F12*D12 -> 4518.25 | H12: =INDIRECT("'" & $S$2 & "'!H" & ROW()) + G12 -> 17490 | I12: =IF($N$9=0,0,D12/$N$9*1000)*1000 -> 277.59401 | J12: =IF($O$9=0,0,E12/$O$9*1000)*1000 -> 337.95007 | K12: 400 | M12: MOAGEM ( Toneladas )
B13: FERMAPLUS | C13: kg | D13: 1190.56 | E13: =INDIRECT("'" & $S$2 & "'!E" & ROW()) + D13 -> 2060.57 | F13: 6 | G13: =F13*D13 -> 7143.36 | H13: =INDIRECT("'" & $S$2 & "'!H" & ROW()) + G13 -> 12363.42 | I13: =IF($N$9=0,0,D13/$N$9*1000)*1000 -> 426.44171 | J13: =IF($O$9=0,0,E13/$O$9*1000)*1000 -> 232.12326 | K13: 500 | M13: CANA MOÍDA | N13: SEMANA | O13: SAFRA 2025 | P13: SAFRA 2025
B14: MONENSINA | C14: kg | D14: 10 | E14: =INDIRECT("'" & $S$2 & "'!E" & ROW()) + D14 -> 25 | F14: 425 | G14: =F14*D14 -> 4250 | H14: =INDIRECT("'" & $S$2 & "'!H" & ROW()) + G14 -> 10625 | I14: =IF($N$9=0,0,D14/$N$9*1000)*1000 -> 3.5818582 | J14: =IF($O$9=0,0,E14/$O$9*1000)*1000 -> 2.8162506 | K14: 3 | M14: PARA ETANOL | N14: 35291.164 | O14: =INDIRECT("'" & $S$2 & "'!O" & ROW()) + N14 -> 121937.59 | P14: 52223.818
M15: PARA AÇÚCAR | N15: 30508.636 | O15: =INDIRECT("'" & $S$2 & "'!O" & ROW()) + N15 -> 105771.59 | P15: 83425.142
B16: Fábrica | D16: Consumo | F16: Custos( R$ ) | I16: Gr / tc | M16: MOÍDA TOTAL | N16: =SUM(N14:N15) -> 65799.8 | O16: =SUM(O14:O15) -> 227709.18 | P16: =P15+P14 -> 135648.96
D17: SEMANAL | E17: SAFRA | F17: VALOR | G17: SEMANA | H17: SAFRA | I17: SEMANA | J17: SAFRA | K17: META
B18: FLOCULANTE | C18: kg | D18: 275 | E18: =INDIRECT("'" & $S$2 & "'!E" & ROW()) + D18 -> 1325 | F18: 21 | G18: =D18*F18 -> 5775 | H18: =INDIRECT("'" & $S$2 & "'!H" & ROW()) + G18 -> 27825 | I18: =IF($N$10=0,0,D18/$N$16*1000) -> 4.179344 | J18: =IF($O$10=0,0,E18/$O$16*1000) -> 5.8188256 | K18: 6.1 | M18: SETOR | N18: SEMANA | O18: SAFRA 2025
B19: FLOCUL. FILTRO | C19: kg | D19: 450 | E19: =INDIRECT("'" & $S$2 & "'!E" & ROW()) + D19 -> 1550 | F19: 15.63 | G19: =D19*F19 -> 7033.5 | H19: =INDIRECT("'" & $S$2 & "'!H" & ROW()) + G19 -> 24226.5 | I19: =IF($N$10=0,0,D19/$N$16*1000) -> 6.8389266 | J19: =IF($O$10=0,0,E19/$O$16*1000) -> 6.806928 | K19: 9 | M19: DESTILARIA | N19: =SUM(G6:G14) -> 105167.41 | O19: =INDIRECT("'" & $S$2 & "'!O" & ROW()) + N19 -> 403492.72
B20: ENXOFRE | C20: kg | E20: =INDIRECT("'" & $S$2 & "'!E" & ROW()) + D20 -> 1000 | F20: 6.7 | G20: =D20*F20 -> 0 | H20: =INDIRECT("'" & $S$2 & "'!H" & ROW()) + G20 -> 6700 | I20: =IF($N$10=0,0,D20/$N$16*1000) -> 0 | J20: =IF($O$10=0,0,E20/$O$16*1000) -> 4.3915665 | K20: 51 | M20: FÁBRICA | N20: =SUM(G18:G27)+G51 -> 62051.926 | O20: =INDIRECT("'" & $S$2 & "'!O" & ROW()) + N20 -> 265699.26
B21: AC.FOSFÓRICO | C21: kg | E21: =INDIRECT("'" & $S$2 & "'!E" & ROW()) + D21 -> 0 | F21: 5.85 | G21: =D21*F21 -> 0 | H21: =INDIRECT("'" & $S$2 & "'!H" & ROW()) + G21 -> 0 | I21: =IF($N$10=0,0,D21/$N$16*1000) -> 0 | J21: =IF($O$10=0,0,E21/$O$16*1000) -> 0 | M21: MOENDA | N21: =SUM(G30:G37) -> 7644.7776 | O21: =INDIRECT("'" & $S$2 & "'!O" & ROW()) + N21 -> 29507.256
B22: CAL DOLOMÍTICA | C22: kg | D22: 20379.5 | E22: =INDIRECT("'" & $S$2 & "'!E" & ROW()) + D22 -> 112972.1 | F22: 1.03 | G22: =D22*F22 -> 20990.885 | H22: =INDIRECT("'" & $S$2 & "'!H" & ROW()) + G22 -> 116361.26 | I22: =IF($N$10=0,0,D22/$N$16*1000) -> 309.71979 | J22: =IF($O$10=0,0,E22/$O$16*1000) -> 496.12449 | K22: 1000 | M22: ETA/CALD. | N22: =SUM(G40:G53)-G51 -> 11346.926 | O22: =INDIRECT("'" & $S$2 & "'!O" & ROW()) + N22 -> 62051.254
B23: SODA CÁUSTICA | C23: kg | D23: 475 | E23: =INDIRECT("'" & $S$2 & "'!E" & ROW()) + D23 -> 2425 | F23: 5.83 | G23: =D23*F23 -> 2769.25 | H23: =INDIRECT("'" & $S$2 & "'!H" & ROW()) + G23 -> 14137.75 | I23: =IF($N$10=0,0,D23/$N$16*1000) -> 7.2188669 | J23: =IF($O$10=0,0,E23/$O$16*1000) -> 10.649549 | K23: 13 | M23: CUSTO TOTAL (R$ ) | N23: =SUM(N19:N22) -> 186211.04 | O23: =SUM(O19:O22) -> 760750.49
B24: NEUT.VAPOR | C24: kg | D24: 1519.99 | E24: =INDIRECT("'" & $S$2 & "'!E" & ROW()) + D24 -> 3849.99 | F24: 8 | G24: =D24*F24 -> 12159.92 | H24: =INDIRECT("'" & $S$2 & "'!H" & ROW()) + G24 -> 30799.92 | I24: =IF($N$10=0,0,D24/$N$16*1000) -> 23.100222 | J24: =IF($O$10=0,0,E24/$O$16*1000) -> 16.907487 | K24: 2.8
B25: ANTI-INCRUST. | C25: kg | D25: 2083.53 | E25: =INDIRECT("'" & $S$2 & "'!E" & ROW()) + D25 -> 7415.28 | F25: 5.85 | G25: =D25*F25 -> 12188.65 | H25: =INDIRECT("'" & $S$2 & "'!H" & ROW()) + G25 -> 43379.388 | I25: =IF($N$10=0,0,D25/$N$16*1000) -> 31.664686 | J25: =IF($O$10=0,0,E25/$O$16*1000) -> 32.564695 | K25: 28 | M25: Setor | N25: Semana | P25: Safra 2025
B26: CLARIFICANTE FL 40 | C26: Kg | E26: =INDIRECT("'" & $S$2 & "'!E" & ROW()) + D26 -> 0 | F26: 6.98 | G26: =D26*F26 -> 0 | H26: =INDIRECT("'" & $S$2 & "'!H" & ROW()) + G26 -> 0 | I26: =IF($N$10=0,0,D26/$N$16*1000) -> 0 | J26: =IF($O$10=0,0,E26/$O$16*1000) -> 0 | K26: 21.3 | M26: DESTILARIA | N26: =IF($N$9=0,0,N19/$N$9*1000) -> 37.669476 | O26: R$/m³ | P26: =IF($O$9=0,0,O19/$O$9*1000) -> 45.453465 | Q26: R$/m³
B27: LUBRIFICANTE MASSA | C27: Kg | E27: =INDIRECT("'" & $S$2 & "'!E" & ROW()) + D27 -> 0 | G27: =D27*F27 -> 0 | H27: =INDIRECT("'" & $S$2 & "'!H" & ROW()) + G27 -> 0 | I27: =IF($N$10=0,0,D27/$N$16*1000) -> 0 | J27: =IF($O$10=0,0,E27/$O$16*1000) -> 0 | K27: 3.6 | M27: FÁBRICA | N27: =IF($N$10=0,0,N20/$N$16) -> 0.94304125 | O27: R$/tc | P27: =IF($O$10=0,0,O20/$O$16) -> 1.166836 | Q27: R$/tc
B28: Moenda | D28: Consumo | F28: Custos( R$ ) | I28: Gr / tc | M28: MOENDA | N28: =IF($N$16=0,0,N21/$N$16) -> 0.11618238 | O28: R$/tc | P28: =IF($O$16=0,0,O21/$O$16) -> 0.12958308 | Q28: R$/tc
D29: SEMANAL | E29: SAFRA | F29: VALOR | G29: SEMANA | H29: SAFRA | I29: SEMANA | J29: SAFRA | K29: META | M29: ETA/CALD. | N29: =IF($N$16=0,0,N22/$N$16) -> 0.17244621 | O29: R$/tc | P29: =IF($O$16=0,0,O22/$O$16) -> 0.27250221 | Q29: R$/tc
B30: CAL VIRGEM | C30: kg | E30: =INDIRECT("'" & $S$2 & "'!E" & ROW()) + D30 -> 0 | F30: 1.03 | G30: =D30*F30 -> 0 | H30: =INDIRECT("'" & $S$2 & "'!H" & ROW()) + G30 -> 0 | I30: =IF($N$16=0,0,D30/$N$16*1000) -> 0 | J30: =IF($O$16=0,0,E30/$O$16*1000) -> 0 | K30: 0 | M30: TOTAL | N30: =IF($N$16=0,0,N23/$N$16) -> 2.8299637 | O30: R$/tc | P30: =IF($O$16=0,0,O23/$O$16) -> 3.3408864 | Q30: R$/tc
B31: SODA CÁUSTICA | C31: kg | D31: 25 | E31: =INDIRECT("'" & $S$2 & "'!E" & ROW()) + D31 -> 100 | F31: 5.83 | G31: =D31*F31 -> 145.75 | H31: =INDIRECT("'" & $S$2 & "'!H" & ROW()) + G31 -> 583 | I31: =IF($N$16=0,0,D31/$N$16*1000) -> 0.37994036 | J31: =IF($O$16=0,0,E31/$O$16*1000) -> 0.43915665 | K31: 1.5
B32: BAC.QUATERNARIO | C32: kg | D32: 688.24 | E32: =INDIRECT("'" & $S$2 & "'!E" & ROW()) + D32 -> 2682.37 | F32: 8.99 | G32: =D32*F32 -> 6187.2776 | H32: =INDIRECT("'" & $S$2 & "'!H" & ROW()) + G32 -> 24114.506 | I32: =IF($N$16=0,0,D32/$N$16*1000) -> 10.459606 | J32: =IF($O$16=0,0,E32/$O$16*1000) -> 11.779806 | K32: 8
B33: HELACLOR | C33: kg | E33: =INDIRECT("'" & $S$2 & "'!E" & ROW()) + D33 -> 0 | F33: 24 | G33: =D33*F33 -> 0 | H33: =INDIRECT("'" & $S$2 & "'!H" & ROW()) + G33 -> 0 | I33: =IF($N$16=0,0,D33/$N$16*1000) -> 0 | J33: =IF($O$16=0,0,E33/$O$16*1000) -> 0 | K33: 0
B34: SODA PENEIRA ROTATIVA | C34: Kg | D34: 150 | E34: =INDIRECT("'" & $S$2 & "'!E" & ROW()) + D34 -> 500 | F34: 5.83 | G34: =D34*F34 -> 874.5 | H34: =INDIRECT("'" & $S$2 & "'!H" & ROW()) + G34 -> 2915 | I34: =IF($N$16=0,0,D34/$N$16*1000) -> 2.2796422 | J34: =IF($O$16=0,0,E34/$O$16*1000) -> 2.1957832 | K34: 2
B35: SODA PENEIRA VIBRATÓRIA | C35: kg | D35: 75 | E35: =INDIRECT("'" & $S$2 & "'!E" & ROW()) + D35 -> 325 | F35: 5.83 | G35: =D35*F35 -> 437.25 | H35: =INDIRECT("'" & $S$2 & "'!H" & ROW()) + G35 -> 1894.75 | I35: =IF($N$16=0,0,D35/$N$16*1000) -> 1.1398211 | J35: =IF($O$16=0,0,E35/$O$16*1000) -> 1.4272591 | K35: 1
B36: ESTEIRA METALICA | C36: kg | E36: =INDIRECT("'" & $S$2 & "'!E" & ROW()) + D36 -> 0 | F36: 5.83 | G36: =D36*F36 -> 0 | H36: =INDIRECT("'" & $S$2 & "'!H" & ROW()) + G36 -> 0 | I36: =IF($N$16=0,0,D36/$N$16*1000) -> 0 | J36: =IF($O$16=0,0,E36/$O$16*1000) -> 0 | K36: 1
B38: Caldeira / Eta | D38: Consumo | F38: Custos ( R$ ) | I38: Gr/tc
D39: SEMANAL | E39: SAFRA | F39: VALOR | G39: SEMANA | H39: SAFRA | I39: SEMANA | J39: SAFRA | K39: META
B40: SODA CÁUSTICA | C40: kg | D40: 125 | E40: =INDIRECT("'" & $S$2 & "'!E" & ROW()) + D40 -> 800 | F40: 5.83 | G40: =D40*F40 -> 728.75 | H40: =INDIRECT("'" & $S$2 & "'!H" & ROW()) + G40 -> 4664 | I40: =IF($N$16=0,0,D40/$N$16*1000) -> 1.8997018 | J40: =IF($O$16=0,0,E40/$O$16*1000) -> 3.5132532 | K40: 6
B41: BRW 150 HELAMIN | C41: kg | D41: 100 | E41: =INDIRECT("'" & $S$2 & "'!E" & ROW()) + D41 -> 650 | F41: 37.84 | G41: =D41*F41 -> 3784 | H41: =INDIRECT("'" & $S$2 & "'!H" & ROW()) + G41 -> 24596 | I41: =IF($N$16=0,0,D41/$N$16*1000) -> 1.5197615 | J41: =IF($O$16=0,0,E41/$O$16*1000) -> 2.8545182 | K41: 3
B42: POLÍMERO | C42: kg | D42: 25 | E42: =INDIRECT("'" & $S$2 & "'!E" & ROW()) + D42 -> 63.5 | F42: 21 | G42: =D42*F42 -> 525 | H42: =INDIRECT("'" & $S$2 & "'!H" & ROW()) + G42 -> 1333.5 | I42: =IF($N$16=0,0,D42/$N$16*1000) -> 0.37994036 | J42: =IF($O$16=0,0,E42/$O$16*1000) -> 0.27886447 | K42: 0.35
...

Sheet semana 5
B2: SEMANA | E2: CONSUMO DE PRODUTOS QUÍMICOS SAFRA 2026/2027 | S2: SEMANA 4
B3: 5 | C3: SEMANA 11/05/2026 A 17/05/2026
B4: Destilaria | D4: Consumo | F4: Custos( R$ ) | I4: Gr / m³ | M4: Descrição | N4: Semana | O4: Safra 2026 | P4: Safra 2025
D5: SEMANAL | E5: SAFRA | F5: VALOR | G5: SEMANA | H5: SAFRA | I5: SEMANA | J5: SAFRA | K5: META | M5: AÇÚCAR VHP (scs.) | N5: 71047 | O5: =INDIRECT("'" & $S$2 & "'!O" & ROW()) + N5 -> 314705 | P5: 245951
B6: ÁC.SULFURICO | C6: kg | D6: 9240.21 | E6: =INDIRECT("'" & $S$2 & "'!E" & ROW()) + D6 -> 55565.35 | F6: 8.6 | G6: =F6*D6 -> 79465.806 | H6: =INDIRECT("'" & $S$2 & "'!H" & ROW()) + G6 -> 197131.66 | I6: =IF($N$9=0,0,D6/$N$9*1000) -> 3.5392567 | J6: =IF($O$9=0,0,E6/$O$9*1000) -> 4.8368891 | K6: 9.8 | M6: AÇÚCAR CRISTAL (scs.) | O6: ='semana 1'!O6+N6 -> 0
B7: ANTIBIÓTICO | C7: kg | E7: =INDIRECT("'" & $S$2 & "'!E" & ROW()) + D7 -> 70 | F7: 599 | G7: =F7*D7 -> 0 | H7: =INDIRECT("'" & $S$2 & "'!H" & ROW()) + G7 -> 41930 | I7: =IF($N$9=0,0,D7/$N$9*1000)*1000 -> 0 | J7: =IF($O$9=0,0,E7/$O$9*1000)*1000 -> 6.093406 | K7: 6.8 | M7: ETANOL ANIDRO ( L ) | O7: ='semana 1'!O7+N7 -> 0
B8: ANTIESPUMANTE | C8: kg | D8: 1515 | E8: =INDIRECT("'" & $S$2 & "'!E" & ROW()) + D8 -> 8820 | F8: 15 | G8: =F8*D8 -> 22725 | H8: =INDIRECT("'" & $S$2 & "'!H" & ROW()) + G8 -> 125642.4 | I8: =IF($N$9=0,0,D8/$N$9*1000)*1000 -> 580.28702 | J8: =IF($O$9=0,0,E8/$O$9*1000)*1000 -> 767.76916 | K8: 400 | M8: ETANOL HIDRATADO ( L ) | N8: 2610777 | O8: =INDIRECT("'" & $S$2 & "'!O" & ROW()) + N8 -> 11487828 | P8: 4246894
B9: DISPERSANTE | C9: kg | D9: 923.53 | E9: =INDIRECT("'" & $S$2 & "'!E" & ROW()) + D9 -> 4440.22 | F9: 25.15 | G9: =F9*D9 -> 23226.779 | H9: =INDIRECT("'" & $S$2 & "'!H" & ROW()) + G9 -> 111671.53 | I9: =IF($N$9=0,0,D9/$N$9*1000)*1000 -> 353.7376 | J9: =IF($O$9=0,0,E9/$O$9*1000)*1000 -> 386.51519 | K9: 200 | M9: ETANOL TOTAL | N9: =SUM(N7:N8) -> 2610777 | O9: =SUM(O7:O8) -> 11487828
B10: NEUT.ALCOOL | C10: kg | E10: =INDIRECT("'" & $S$2 & "'!E" & ROW()) + D10 -> 100 | F10: 10.98 | G10: =F10*D10 -> 0 | H10: =INDIRECT("'" & $S$2 & "'!H" & ROW()) + G10 -> 1098 | I10: =IF($N$9=0,0,D10/$N$9*1000)*1000 -> 0 | J10: =IF($O$9=0,0,E10/$O$9*1000)*1000 -> 8.7048657 | K10: 10 | M10: AÇUCAR TOTAL | N10: =SUM(N5:N6) -> 71047 | O10: =SUM(O5:O6) -> 314705
B11: NUTRIENTES | C11: kg | E11: =INDIRECT("'" & $S$2 & "'!E" & ROW()) + D11 -> 2653.34 | F11: 4.13 | G11: =F11*D11 -> 0 | H11: =INDIRECT("'" & $S$2 & "'!H" & ROW()) + G11 -> 10958.294 | I11: =IF($N$9=0,0,D11/$N$9*1000)*1000 -> 0 | J11: =IF($O$9=0,0,E11/$O$9*1000)*1000 -> 230.96968
B12: SODA CÁUSTICA | C12: kg | D12: 925 | E12: =INDIRECT("'" & $S$2 & "'!E" & ROW()) + D12 -> 3925 | F12: 5.83 | G12: =F12*D12 -> 5392.75 | H12: =INDIRECT("'" & $S$2 & "'!H" & ROW()) + G12 -> 22882.75 | I12: =IF($N$9=0,0,D12/$N$9*1000)*1000 -> 354.30065 | J12: =IF($O$9=0,0,E12/$O$9*1000)*1000 -> 341.66598 | K12: 400 | M12: MOAGEM ( Toneladas )
B13: FERMAPLUS | C13: kg | D13: 1008.33 | E13: =INDIRECT("'" & $S$2 & "'!E" & ROW()) + D13 -> 3068.9 | F13: 6 | G13: =F13*D13 -> 6049.98 | H13: =INDIRECT("'" & $S$2 & "'!H" & ROW()) + G13 -> 18413.4 | I13: =IF($N$9=0,0,D13/$N$9*1000)*1000 -> 386.21836 | J13: =IF($O$9=0,0,E13/$O$9*1000)*1000 -> 267.14362 | K13: 500 | M13: CANA MOÍDA | N13: SEMANA | O13: SAFRA 2026 | P13: SAFRA 2025
B14: MONENSINA | C14: kg | D14: 10 | E14: =INDIRECT("'" & $S$2 & "'!E" & ROW()) + D14 -> 35 | F14: 425 | G14: =F14*D14 -> 4250 | H14: =INDIRECT("'" & $S$2 & "'!H" & ROW()) + G14 -> 14875 | I14: =IF($N$9=0,0,D14/$N$9*1000)*1000 -> 3.8302773 | J14: =IF($O$9=0,0,E14/$O$9*1000)*1000 -> 3.046703 | K14: 3 | M14: PARA ETANOL | N14: 30411.884 | O14: =INDIRECT("'" & $S$2 & "'!O" & ROW()) + N14 -> 152349.47 | P14: 69741.637
M15: PARA AÇÚCAR | N15: 26523.216 | O15: =INDIRECT("'" & $S$2 & "'!O" & ROW()) + N15 -> 132294.8 | P15: 118996.26
B16: Fábrica | D16: Consumo | F16: Custos( R$ ) | I16: Gr / tc | M16: MOÍDA TOTAL | N16: =SUM(N14:N15) -> 56935.1 | O16: =SUM(O14:O15) -> 284644.28 | P16: =P15+P14 -> 188737.9
D17: SEMANAL | E17: SAFRA | F17: VALOR | G17: SEMANA | H17: SAFRA | I17: SEMANA | J17: SAFRA | K17: META
B18: FLOCULANTE | C18: kg | D18: 275 | E18: =INDIRECT("'" & $S$2 & "'!E" & ROW()) + D18 -> 1600 | F18: 21 | G18: =D18*F18 -> 5775 | H18: =INDIRECT("'" & $S$2 & "'!H" & ROW()) + G18 -> 33600 | I18: =IF($N$10=0,0,D18/$N$16*1000) -> 4.8300609 | J18: =IF($O$10=0,0,E18/$O$16*1000) -> 5.6210509 | K18: 6.1 | M18: SETOR | N18: SEMANA | O18: SAFRA 2026
B19: FLOCUL. FILTRO | C19: kg | D19: 150 | E19: =INDIRECT("'" & $S$2 & "'!E" & ROW()) + D19 -> 1700 | F19: 15.63 | G19: =D19*F19 -> 2344.5 | H19: =INDIRECT("'" & $S$2 & "'!H" & ROW()) + G19 -> 26571 | I19: =IF($N$10=0,0,D19/$N$16*1000) -> 2.6345787 | J19: =IF($O$10=0,0,E19/$O$16*1000) -> 5.9723666 | K19: 9 | M19: DESTILARIA | N19: =SUM(G6:G14) -> 141110.32 | O19: =INDIRECT("'" & $S$2 & "'!O" & ROW()) + N19 -> 544603.04
B20: ENXOFRE | C20: kg | E20: =INDIRECT("'" & $S$2 & "'!E" & ROW()) + D20 -> 1000 | F20: 6.7 | G20: =D20*F20 -> 0 | H20: =INDIRECT("'" & $S$2 & "'!H" & ROW()) + G20 -> 6700 | I20: =IF($N$10=0,0,D20/$N$16*1000) -> 0 | J20: =IF($O$10=0,0,E20/$O$16*1000) -> 3.5131568 | K20: 51 | M20: FÁBRICA | N20: =SUM(G18:G27)+G51 -> 55207.099 | O20: =INDIRECT("'" & $S$2 & "'!O" & ROW()) + N20 -> 320906.36
B21: AC.FOSFÓRICO | C21: kg | E21: =INDIRECT("'" & $S$2 & "'!E" & ROW()) + D21 -> 0 | F21: 5.85 | G21: =D21*F21 -> 0 | H21: =INDIRECT("'" & $S$2 & "'!H" & ROW()) + G21 -> 0 | I21: =IF($N$10=0,0,D21/$N$16*1000) -> 0 | J21: =IF($O$10=0,0,E21/$O$16*1000) -> 0 | M21: MOENDA | N21: =SUM(G30:G37) -> 8134.8888 | O21: =INDIRECT("'" & $S$2 & "'!O" & ROW()) + N21 -> 37642.145
B22: CAL DOLOMÍTICA | C22: kg | D22: 23719.8 | E22: =INDIRECT("'" & $S$2 & "'!E" & ROW()) + D22 -> 136691.9 | F22: 1.03 | G22: =D22*F22 -> 24431.394 | H22: =INDIRECT("'" & $S$2 & "'!H" & ROW()) + G22 -> 140792.66 | I22: =IF($N$10=0,0,D22/$N$16*1000) -> 416.61119 | J22: =IF($O$10=0,0,E22/$O$16*1000) -> 480.22008 | K22: 1000 | M22: ETA/CALD. | N22: =SUM(G40:G53)-G51 -> 11898.862 | O22: =INDIRECT("'" & $S$2 & "'!O" & ROW()) + N22 -> 73950.116
B23: SODA CÁUSTICA | C23: kg | D23: 450 | E23: =INDIRECT("'" & $S$2 & "'!E" & ROW()) + D23 -> 2875 | F23: 5.83 | G23: =D23*F23 -> 2623.5 | H23: =INDIRECT("'" & $S$2 & "'!H" & ROW()) + G23 -> 16761.25 | I23: =IF($N$10=0,0,D23/$N$16*1000) -> 7.903736 | J23: =IF($O$10=0,0,E23/$O$16*1000) -> 10.100326 | K23: 13 | M23: CUSTO TOTAL (R$ ) | N23: =SUM(N19:N22) -> 216351.17 | O23: =SUM(O19:O22) -> 977101.66
B24: NEUT.VAPOR | C24: kg | D24: 838.88 | E24: =INDIRECT("'" & $S$2 & "'!E" & ROW()) + D24 -> 4688.87 | F24: 8 | G24: =D24*F24 -> 6711.04 | H24: =INDIRECT("'" & $S$2 & "'!H" & ROW()) + G24 -> 37510.96 | I24: =IF($N$10=0,0,D24/$N$16*1000) -> 14.733969 | J24: =IF($O$10=0,0,E24/$O$16*1000) -> 16.472736 | K24: 2.8
B25: ANTI-INCRUST. | C25: kg | D25: 1695.3 | E25: =INDIRECT("'" & $S$2 & "'!E" & ROW()) + D25 -> 9110.58 | F25: 5.85 | G25: =D25*F25 -> 9917.505 | H25: =INDIRECT("'" & $S$2 & "'!H" & ROW()) + G25 -> 53296.893 | I25: =IF($N$10=0,0,D25/$N$16*1000) -> 29.776008 | J25: =IF($O$10=0,0,E25/$O$16*1000) -> 32.006896 | K25: 28 | M25: Setor | N25: Semana | P25: Safra 2026
B26: CLARIFICANTE FL 40 | C26: Kg | E26: =INDIRECT("'" & $S$2 & "'!E" & ROW()) + D26 -> 0 | F26: 6.98 | G26: =D26*F26 -> 0 | H26: =INDIRECT("'" & $S$2 & "'!H" & ROW()) + G26 -> 0 | I26: =IF($N$10=0,0,D26/$N$16*1000) -> 0 | J26: =IF($O$10=0,0,E26/$O$16*1000) -> 0 | K26: 21.3 | M26: DESTILARIA | N26: =IF($N$9=0,0,N19/$N$9*1000) -> 54.049164 | O26: R$/m³ | P26: =IF($O$9=0,0,O19/$O$9*1000) -> 47.406963 | Q26: R$/m³
B27: LUBRIFICANTE MASSA | C27: Kg | E27: =INDIRECT("'" & $S$2 & "'!E" & ROW()) + D27 -> 0 | G27: =D27*F27 -> 0 | H27: =INDIRECT("'" & $S$2 & "'!H" & ROW()) + G27 -> 0 | I27: =IF($N$10=0,0,D27/$N$16*1000) -> 0 | J27: =IF($O$10=0,0,E27/$O$16*1000) -> 0 | K27: 3.6 | M27: FÁBRICA | N27: =IF($N$10=0,0,N20/$N$16) -> 0.96964964 | O27: R$/tc | P27: =IF($O$10=0,0,O20/$O$16) -> 1.1273944 | Q27: R$/tc
B28: Moenda | D28: Consumo | F28: Custos( R$ ) | I28: Gr / tc | M28: MOENDA | N28: =IF($N$16=0,0,N21/$N$16) -> 0.14288003 | O28: R$/tc | P28: =IF($O$16=0,0,O21/$O$16) -> 0.13224276 | Q28: R$/tc
D29: SEMANAL | E29: SAFRA | F29: VALOR | G29: SEMANA | H29: SAFRA | I29: SEMANA | J29: SAFRA | K29: META | M29: ETA/CALD. | N29: =IF($N$16=0,0,N22/$N$16) -> 0.20898992 | O29: R$/tc | P29: =IF($O$16=0,0,O22/$O$16) -> 0.25979836 | Q29: R$/tc
B30: CAL VIRGEM | C30: kg | E30: =INDIRECT("'" & $S$2 & "'!E" & ROW()) + D30 -> 0 | F30: 1.03 | G30: =D30*F30 -> 0 | H30: =INDIRECT("'" & $S$2 & "'!H" & ROW()) + G30 -> 0 | I30: =IF($N$16=0,0,D30/$N$16*1000) -> 0 | J30: =IF($O$16=0,0,E30/$O$16*1000) -> 0 | K30: 0 | M30: TOTAL | N30: =IF($N$16=0,0,N23/$N$16) -> 3.7999611 | O30: R$/tc | P30: =IF($O$16=0,0,O23/$O$16) -> 3.4327114 | Q30: R$/tc
B31: SODA CÁUSTICA | C31: kg | D31: 100 | E31: =INDIRECT("'" & $S$2 & "'!E" & ROW()) + D31 -> 200 | F31: 5.83 | G31: =D31*F31 -> 583 | H31: =INDIRECT("'" & $S$2 & "'!H" & ROW()) + G31 -> 1166 | I31: =IF($N$16=0,0,D31/$N$16*1000) -> 1.7563858 | J31: =IF($O$16=0,0,E31/$O$16*1000) -> 0.70263137 | K31: 1.5
B32: BAC.QUATERNARIO | C32: kg | D32: 694.12 | E32: =INDIRECT("'" & $S$2 & "'!E" & ROW()) + D32 -> 3376.49 | F32: 8.99 | G32: =D32*F32 -> 6240.1388 | H32: =INDIRECT("'" & $S$2 & "'!H" & ROW()) + G32 -> 30354.645 | I32: =IF($N$16=0,0,D32/$N$16*1000) -> 12.191425 | J32: =IF($O$16=0,0,E32/$O$16*1000) -> 11.862139 | K32: 8
B33: HELACLOR | C33: kg | E33: =INDIRECT("'" & $S$2 & "'!E" & ROW()) + D33 -> 0 | F33: 24 | G33: =D33*F33 -> 0 | H33: =INDIRECT("'" & $S$2 & "'!H" & ROW()) + G33 -> 0 | I33: =IF($N$16=0,0,D33/$N$16*1000) -> 0 | J33: =IF($O$16=0,0,E33/$O$16*1000) -> 0 | K33: 0
B34: SODA PENEIRA ROTATIVA | C34: Kg | D34: 125 | E34: =INDIRECT("'" & $S$2 & "'!E" & ROW()) + D34 -> 625 | F34: 5.83 | G34: =D34*F34 -> 728.75 | H34: =INDIRECT("'" & $S$2 & "'!H" & ROW()) + G34 -> 3643.75 | I34: =IF($N$16=0,0,D34/$N$16*1000) -> 2.1954822 | J34: =IF($O$16=0,0,E34/$O$16*1000) -> 2.195723 | K34: 2
B35: SODA PENEIRA VIBRATÓRIA | C35: kg | D35: 100 | E35: =INDIRECT("'" & $S$2 & "'!E" & ROW()) + D35 -> 425 | F35: 5.83 | G35: =D35*F35 -> 583 | H35: =INDIRECT("'" & $S$2 & "'!H" & ROW()) + G35 -> 2477.75 | I35: =IF($N$16=0,0,D35/$N$16*1000) -> 1.7563858 | J35: =IF($O$16=0,0,E35/$O$16*1000) -> 1.4930917 | K35: 1
B36: ESTEIRA METALICA | C36: kg | E36: =INDIRECT("'" & $S$2 & "'!E" & ROW()) + D36 -> 0 | F36: 5.83 | G36: =D36*F36 -> 0 | H36: =INDIRECT("'" & $S$2 & "'!H" & ROW()) + G36 -> 0 | I36: =IF($N$16=0,0,D36/$N$16*1000) -> 0 | J36: =IF($O$16=0,0,E36/$O$16*1000) -> 0 | K36: 1
B38: Caldeira / Eta | D38: Consumo | F38: Custos ( R$ ) | I38: Gr/tc
D39: SEMANAL | E39: SAFRA | F39: VALOR | G39: SEMANA | H39: SAFRA | I39: SEMANA | J39: SAFRA | K39: META
B40: SODA CÁUSTICA | C40: kg | D40: 250 | E40: =INDIRECT("'" & $S$2 & "'!E" & ROW()) + D40 -> 1050 | F40: 5.83 | G40: =D40*F40 -> 1457.5 | H40: =INDIRECT("'" & $S$2 & "'!H" & ROW()) + G40 -> 6121.5 | I40: =IF($N$16=0,0,D40/$N$16*1000) -> 4.3909644 | J40: =IF($O$16=0,0,E40/$O$16*1000) -> 3.6888147 | K40: 6
B41: BRW 150 HELAMIN | C41: kg | D41: 150 | E41: =INDIRECT("'" & $S$2 & "'!E" & ROW()) + D41 -> 800 | F41: 37.84 | G41: =D41*F41 -> 5676 | H41: =INDIRECT("'" & $S$2 & "'!H" & ROW()) + G41 -> 30272 | I41: =IF($N$16=0,0,D41/$N$16*1000) -> 2.6345787 | J41: =IF($O$16=0,0,E41/$O$16*1000) -> 2.8105255 | K41: 3
B42: POLÍMERO | C42: kg | E42: =INDIRECT("'" & $S$2 & "'!E" & ROW()) + D42 -> 63.5 | F42: 21 | G42: =D42*F42 -> 0 | H42: =INDIRECT("'" & $S$2 & "'!H" & ROW()) + G42 -> 1333.5 | I42: =IF($N$16=0,0,D42/$N$16*1000) -> 0 | J42: =IF($O$16=0,0,E42/$O$16*1000) -> 0.22308546 | K42: 0.35
...

Sheet semana 6
B2: SEMANA | E2: CONSUMO DE PRODUTOS QUÍMICOS SAFRA 2026/2027 | S2: SEMANA 5
B3: 6 | C3: SEMANA 18/05/2026 A 24/05/2026
B4: Destilaria | D4: Consumo | F4: Custos( R$ ) | I4: Gr / m³ | M4: Descrição | N4: Semana | O4: Safra 2026 | P4: Safra 2025
D5: SEMANAL | E5: SAFRA | F5: VALOR | G5: SEMANA | H5: SAFRA | I5: SEMANA | J5: SAFRA | K5: META | M5: AÇÚCAR VHP (scs.) | N5: 77204 | O5: =INDIRECT("'" & $S$2 & "'!O" & ROW()) + N5 -> 391909 | P5: 334420
B6: ÁC.SULFURICO | C6: kg | D6: 8767 | E6: =INDIRECT("'" & $S$2 & "'!E" & ROW()) + D6 -> 64332.35 | F6: 8.6 | G6: =F6*D6 -> 75396.2 | H6: =INDIRECT("'" & $S$2 & "'!H" & ROW()) + G6 -> 272527.86 | I6: =IF($N$9=0,0,D6/$N$9*1000) -> 3.6663968 | J6: =IF($O$9=0,0,E6/$O$9*1000) -> 4.6352281 | K6: 9.8 | M6: AÇÚCAR CRISTAL (scs.) | O6: ='semana 1'!O6+N6 -> 0
B7: ANTIBIÓTICO | C7: kg | D7: 30 | E7: =INDIRECT("'" & $S$2 & "'!E" & ROW()) + D7 -> 100 | F7: 599 | G7: =F7*D7 -> 17970 | H7: =INDIRECT("'" & $S$2 & "'!H" & ROW()) + G7 -> 59900 | I7: =IF($N$9=0,0,D7/$N$9*1000)*1000 -> 12.546128 | J7: =IF($O$9=0,0,E7/$O$9*1000)*1000 -> 7.205128 | K7: 6.8 | M7: ETANOL ANIDRO ( L ) | O7: ='semana 1'!O7+N7 -> 0
B8: ANTIESPUMANTE | C8: kg | D8: 955 | E8: =INDIRECT("'" & $S$2 & "'!E" & ROW()) + D8 -> 9775 | F8: 15 | G8: =F8*D8 -> 14325 | H8: =INDIRECT("'" & $S$2 & "'!H" & ROW()) + G8 -> 139967.4 | I8: =IF($N$9=0,0,D8/$N$9*1000)*1000 -> 399.38507 | J8: =IF($O$9=0,0,E8/$O$9*1000)*1000 -> 704.30126 | K8: 400 | M8: ETANOL HIDRATADO ( L ) | N8: 2391176 | O8: =INDIRECT("'" & $S$2 & "'!O" & ROW()) + N8 -> 13879004 | P8: 5400069
B9: DISPERSANTE | C9: kg | D9: 858.83 | E9: =INDIRECT("'" & $S$2 & "'!E" & ROW()) + D9 -> 5299.05 | F9: 25.15 | G9: =F9*D9 -> 21599.574 | H9: =INDIRECT("'" & $S$2 & "'!H" & ROW()) + G9 -> 133271.11 | I9: =IF($N$9=0,0,D9/$N$9*1000)*1000 -> 359.16637 | J9: =IF($O$9=0,0,E9/$O$9*1000)*1000 -> 381.80333 | K9: 200 | M9: ETANOL TOTAL | N9: =SUM(N7:N8) -> 2391176 | O9: =SUM(O7:O8) -> 13879004
B10: NEUT.ALCOOL | C10: kg | D10: 50 | E10: =INDIRECT("'" & $S$2 & "'!E" & ROW()) + D10 -> 150 | F10: 10.98 | G10: =F10*D10 -> 549 | H10: =INDIRECT("'" & $S$2 & "'!H" & ROW()) + G10 -> 1647 | I10: =IF($N$9=0,0,D10/$N$9*1000)*1000 -> 20.910213 | J10: =IF($O$9=0,0,E10/$O$9*1000)*1000 -> 10.807692 | K10: 10 | M10: AÇUCAR TOTAL | N10: =SUM(N5:N6) -> 77204 | O10: =SUM(O5:O6) -> 391909
B11: NUTRIENTES | C11: kg | E11: =INDIRECT("'" & $S$2 & "'!E" & ROW()) + D11 -> 2653.34 | F11: 4.13 | G11: =F11*D11 -> 0 | H11: =INDIRECT("'" & $S$2 & "'!H" & ROW()) + G11 -> 10958.294 | I11: =IF($N$9=0,0,D11/$N$9*1000)*1000 -> 0 | J11: =IF($O$9=0,0,E11/$O$9*1000)*1000 -> 191.17654
B12: SODA CÁUSTICA | C12: kg | D12: 575 | E12: =INDIRECT("'" & $S$2 & "'!E" & ROW()) + D12 -> 4500 | F12: 5.83 | G12: =F12*D12 -> 3352.25 | H12: =INDIRECT("'" & $S$2 & "'!H" & ROW()) + G12 -> 26235 | I12: =IF($N$9=0,0,D12/$N$9*1000)*1000 -> 240.46745 | J12: =IF($O$9=0,0,E12/$O$9*1000)*1000 -> 324.23076 | K12: 400 | M12: MOAGEM ( Toneladas )
B13: FERMAPLUS | C13: kg | D13: 1057.24 | E13: =INDIRECT("'" & $S$2 & "'!E" & ROW()) + D13 -> 4126.14 | F13: 6 | G13: =F13*D13 -> 6343.44 | H13: =INDIRECT("'" & $S$2 & "'!H" & ROW()) + G13 -> 24756.84 | I13: =IF($N$9=0,0,D13/$N$9*1000)*1000 -> 442.14228 | J13: =IF($O$9=0,0,E13/$O$9*1000)*1000 -> 297.29367 | K13: 500 | M13: CANA MOÍDA | N13: SEMANA | O13: SAFRA 2026 | P13: SAFRA 2025
B14: MONENSINA | C14: kg | E14: =INDIRECT("'" & $S$2 & "'!E" & ROW()) + D14 -> 35 | F14: 425 | G14: =F14*D14 -> 0 | H14: =INDIRECT("'" & $S$2 & "'!H" & ROW()) + G14 -> 14875 | I14: =IF($N$9=0,0,D14/$N$9*1000)*1000 -> 0 | J14: =IF($O$9=0,0,E14/$O$9*1000)*1000 -> 2.5217948 | K14: 3 | M14: PARA ETANOL | N14: 33249.99 | O14: =INDIRECT("'" & $S$2 & "'!O" & ROW()) + N14 -> 185599.46 | P14: 85049.835
M15: PARA AÇÚCAR | N15: 32063.99 | O15: =INDIRECT("'" & $S$2 & "'!O" & ROW()) + N15 -> 164358.79 | P15: 154756.08
B16: Fábrica | D16: Consumo | F16: Custos( R$ ) | I16: Gr / tc | M16: MOÍDA TOTAL | N16: =SUM(N14:N15) -> 65313.98 | O16: =SUM(O14:O15) -> 349958.26 | P16: =P15+P14 -> 239805.92
D17: SEMANAL | E17: SAFRA | F17: VALOR | G17: SEMANA | H17: SAFRA | I17: SEMANA | J17: SAFRA | K17: META
B18: FLOCULANTE | C18: kg | D18: 275 | E18: =INDIRECT("'" & $S$2 & "'!E" & ROW()) + D18 -> 1875 | F18: 21 | G18: =D18*F18 -> 5775 | H18: =INDIRECT("'" & $S$2 & "'!H" & ROW()) + G18 -> 39375 | I18: =IF($N$10=0,0,D18/$N$16*1000) -> 4.2104309 | J18: =IF($O$10=0,0,E18/$O$16*1000) -> 5.3577818 | K18: 6.1 | M18: SETOR | N18: SEMANA | O18: SAFRA 2026
B19: FLOCUL. FILTRO | C19: kg | D19: 175 | E19: =INDIRECT("'" & $S$2 & "'!E" & ROW()) + D19 -> 1875 | F19: 15.63 | G19: =D19*F19 -> 2735.25 | H19: =INDIRECT("'" & $S$2 & "'!H" & ROW()) + G19 -> 29306.25 | I19: =IF($N$10=0,0,D19/$N$16*1000) -> 2.6793651 | J19: =IF($O$10=0,0,E19/$O$16*1000) -> 5.3577818 | K19: 9 | M19: DESTILARIA | N19: =SUM(G6:G14) -> 139535.46 | O19: =INDIRECT("'" & $S$2 & "'!O" & ROW()) + N19 -> 684138.5
B20: ENXOFRE | C20: kg | E20: =INDIRECT("'" & $S$2 & "'!E" & ROW()) + D20 -> 1000 | F20: 6.7 | G20: =D20*F20 -> 0 | H20: =INDIRECT("'" & $S$2 & "'!H" & ROW()) + G20 -> 6700 | I20: =IF($N$10=0,0,D20/$N$16*1000) -> 0 | J20: =IF($O$10=0,0,E20/$O$16*1000) -> 2.8574836 | K20: 51 | M20: FÁBRICA | N20: =SUM(G18:G27)+G51 -> 55937.088 | O20: =INDIRECT("'" & $S$2 & "'!O" & ROW()) + N20 -> 376843.45
B21: AC.FOSFÓRICO | C21: kg | E21: =INDIRECT("'" & $S$2 & "'!E" & ROW()) + D21 -> 0 | F21: 5.85 | G21: =D21*F21 -> 0 | H21: =INDIRECT("'" & $S$2 & "'!H" & ROW()) + G21 -> 0 | I21: =IF($N$10=0,0,D21/$N$16*1000) -> 0 | J21: =IF($O$10=0,0,E21/$O$16*1000) -> 0 | M21: MOENDA | N21: =SUM(G30:G37) -> 10268.663 | O21: =INDIRECT("'" & $S$2 & "'!O" & ROW()) + N21 -> 47910.808
